Workbook

Sheet Spreads
A1: Input 1st Leg | D1: Pairing Legs | F1: Trading View Codes | H1: Robot Codes | J1: 2nd Legs Parameters | L1: Tuning | Q1: Input 2nd Leg | V1: Additional 2nd Leg | AC1: Exchange
A2: Instrument 1 | B2: Product Code 1 | C2: Exp 1 | D2: Underl MOEX | E2: Underl CME | F2: Spread for TView | G2: Final Date of Spread | H2: Robot 1 leg | I2: Robot 2 leg | J2: Инструмент 2 | K2: Exp Date 2 | L2: Date corr | M2: Date Diff | N2: UL corr | Q2: Product Code | R2: First Trade | S2: Last Trade | T2: Settlement | U2: FND | V2: Final Date | W2: Underl CME | X2: Exch | Z2: constructor own | AC2: Underl2 | AD2: Exch
A3: BR-4.26 | B3: BRJ6 | C3: 46113 | D3: =MID(A3,1,SEARCH("-",A3,1)-1) -> BR | E3: BZ | F3: ="RUS:"&MID(B3,1,LEN(B3)-1)&"20"&RIGHT(A3,2)&"-"&INDEX(X:X, MATCH(J3,Q:Q,0))&":"&IF(N3="", MID(J3,1,LEN(J3)-2), N3&MID(J3,LEN(J3)-2,1))&"20"&RIGHT(J3,2) -> RUS:BRJ2026-NYMEX:BZK2026 | G3: =MIN(C3,K3) -> 46112 | H3: =A3 -> BR-4.26 | I3: ="QR_"&IF(N3="", MID(J3,1,LEN(J3)-2)&RIGHT(J3),N3&MID(J3,LEN(J3)-2,1)&RIGHT(J3)) -> QR_BZK6 | J3: {=INDEX(Q:Q,MATCH(1, (W:W=E3)*(V:V>=C3-L3)*(V:V<=C3+L3), 0))} -> BZK26 | K3: =INDEX(V:V, MATCH(J3,Q:Q,0)) -> 46112 | L3: 10 | M3: =K3-C3 -> -1 | Q3: NGJ26 | R3: 41605 | S3: 46108 | T3: 46108 | U3: --- | V3: =MIN(S3:U3) -> 46108 | W3: =MID(Q3,1,LEN(Q3)-3) -> NG | X3: =IFERROR(INDEX(AD:AD, MATCH(W3,AC:AC,0)),"---") -> NYMEX | AC3: BZ | AD3: NYMEX
A4: BR-5.26 | B4: BRK6 | C4: 46146 | D4: =MID(A4,1,SEARCH("-",A4,1)-1) -> BR | E4: BZ | F4: ="RUS:"&MID(B4,1,LEN(B4)-1)&"20"&RIGHT(A4,2)&"-"&INDEX(X:X, MATCH(J4,Q:Q,0))&":"&IF(N4="", MID(J4,1,LEN(J4)-2), N4&MID(J4,LEN(J4)-2,1))&"20"&RIGHT(J4,2) -> RUS:BRK2026-NYMEX:BZM2026 | G4: =MIN(C4,K4) -> 46142 | H4: =A4 -> BR-5.26 | I4: ="QR_"&IF(N4="", MID(J4,1,LEN(J4)-2)&RIGHT(J4),N4&MID(J4,LEN(J4)-2,1)&RIGHT(J4)) -> QR_BZM6 | J4: {=INDEX(Q:Q,MATCH(1, (W:W=E4)*(V:V>=C4-L4)*(V:V<=C4+L4), 0))} -> BZM26 | K4: =INDEX(V:V, MATCH(J4,Q:Q,0)) -> 46142 | L4: 10 | M4: =K4-C4 -> -4 | Q4: NGK26 | R4: 41605 | S4: 46140 | T4: 46140 | U4: --- | V4: =MIN(S4:U4) -> 46140 | W4: =MID(Q4,1,LEN(Q4)-3) -> NG | X4: =IFERROR(INDEX(AD:AD, MATCH(W4,AC:AC,0)),"---") -> NYMEX | Z4: consrt robot | AC4: MBT | AD4: CME
A5: BR-6.26 | B5: BRM6 | C5: 46174 | D5: =MID(A5,1,SEARCH("-",A5,1)-1) -> BR | E5: BZ | F5: ="RUS:"&MID(B5,1,LEN(B5)-1)&"20"&RIGHT(A5,2)&"-"&INDEX(X:X, MATCH(J5,Q:Q,0))&":"&IF(N5="", MID(J5,1,LEN(J5)-2), N5&MID(J5,LEN(J5)-2,1))&"20"&RIGHT(J5,2) -> RUS:BRM2026-NYMEX:BZN2026 | G5: =MIN(C5,K5) -> 46171 | H5: =A5 -> BR-6.26 | I5: ="QR_"&IF(N5="", MID(J5,1,LEN(J5)-2)&RIGHT(J5),N5&MID(J5,LEN(J5)-2,1)&RIGHT(J5)) -> QR_BZN6 | J5: {=INDEX(Q:Q,MATCH(1, (W:W=E5)*(V:V>=C5-L5)*(V:V<=C5+L5), 0))} -> BZN26 | K5: =INDEX(V:V, MATCH(J5,Q:Q,0)) -> 46171 | L5: 10 | M5: =K5-C5 -> -3 | Q5: NGM26 | R5: 41605 | S5: 46169 | T5: 46169 | U5: --- | V5: =MIN(S5:U5) -> 46169 | W5: =MID(Q5,1,LEN(Q5)-3) -> NG | X5: =IFERROR(INDEX(AD:AD, MATCH(W5,AC:AC,0)),"---") -> NYMEX | Z5: constr tview | AC5: EC | AD5: CME
A6: BR-7.26 | B6: BRN6 | C6: 46204 | D6: =MID(A6,1,SEARCH("-",A6,1)-1) -> BR | E6: BZ | F6: ="RUS:"&MID(B6,1,LEN(B6)-1)&"20"&RIGHT(A6,2)&"-"&INDEX(X:X, MATCH(J6,Q:Q,0))&":"&IF(N6="", MID(J6,1,LEN(J6)-2), N6&MID(J6,LEN(J6)-2,1))&"20"&RIGHT(J6,2) -> RUS:BRN2026-NYMEX:BZQ2026 | G6: =MIN(C6,K6) -> 46203 | H6: =A6 -> BR-7.26 | I6: ="QR_"&IF(N6="", MID(J6,1,LEN(J6)-2)&RIGHT(J6),N6&MID(J6,LEN(J6)-2,1)&RIGHT(J6)) -> QR_BZQ6 | J6: {=INDEX(Q:Q,MATCH(1, (W:W=E6)*(V:V>=C6-L6)*(V:V<=C6+L6), 0))} -> BZQ26 | K6: =INDEX(V:V, MATCH(J6,Q:Q,0)) -> 46203 | L6: 10 | M6: =K6-C6 -> -1 | Q6: NGN26 | R6: 41605 | S6: 46199 | T6: 46199 | U6: --- | V6: =MIN(S6:U6) -> 46199 | W6: =MID(Q6,1,LEN(Q6)-3) -> NG | X6: =IFERROR(INDEX(AD:AD, MATCH(W6,AC:AC,0)),"---") -> NYMEX | Z6: подписи графиков | AC6: GC | AD6: COMEX
A7: BR-8.26 | B7: BRQ6 | C7: 46237 | D7: =MID(A7,1,SEARCH("-",A7,1)-1) -> BR | E7: BZ | F7: ="RUS:"&MID(B7,1,LEN(B7)-1)&"20"&RIGHT(A7,2)&"-"&INDEX(X:X, MATCH(J7,Q:Q,0))&":"&IF(N7="", MID(J7,1,LEN(J7)-2), N7&MID(J7,LEN(J7)-2,1))&"20"&RIGHT(J7,2) -> RUS:BRQ2026-NYMEX:BZU2026 | G7: =MIN(C7,K7) -> 46234 | H7: =A7 -> BR-8.26 | I7: ="QR_"&IF(N7="", MID(J7,1,LEN(J7)-2)&RIGHT(J7),N7&MID(J7,LEN(J7)-2,1)&RIGHT(J7)) -> QR_BZU6 | J7: {=INDEX(Q:Q,MATCH(1, (W:W=E7)*(V:V>=C7-L7)*(V:V<=C7+L7), 0))} -> BZU26 | K7: =INDEX(V:V, MATCH(J7,Q:Q,0)) -> 46234 | L7: 10 | M7: =K7-C7 -> -3 | Q7: NGQ26 | R7: 41605 | S7: 46232 | T7: 46232 | U7: --- | V7: =MIN(S7:U7) -> 46232 | W7: =MID(Q7,1,LEN(Q7)-3) -> NG | X7: =IFERROR(INDEX(AD:AD, MATCH(W7,AC:AC,0)),"---") -> NYMEX | AC7: NG | AD7: NYMEX
A8: BR-9.26 | B8: BRU6 | C8: 46265 | D8: =MID(A8,1,SEARCH("-",A8,1)-1) -> BR | E8: BZ | F8: ="RUS:"&MID(B8,1,LEN(B8)-1)&"20"&RIGHT(A8,2)&"-"&INDEX(X:X, MATCH(J8,Q:Q,0))&":"&IF(N8="", MID(J8,1,LEN(J8)-2), N8&MID(J8,LEN(J8)-2,1))&"20"&RIGHT(J8,2) -> RUS:BRU2026-NYMEX:BZV2026 | G8: =MIN(C8,K8) -> 46262 | H8: =A8 -> BR-9.26 | I8: ="QR_"&IF(N8="", MID(J8,1,LEN(J8)-2)&RIGHT(J8),N8&MID(J8,LEN(J8)-2,1)&RIGHT(J8)) -> QR_BZV6 | J8: {=INDEX(Q:Q,MATCH(1, (W:W=E8)*(V:V>=C8-L8)*(V:V<=C8+L8), 0))} -> BZV26 | K8: =INDEX(V:V, MATCH(J8,Q:Q,0)) -> 46262 | L8: 10 | M8: =K8-C8 -> -3 | Q8: NGU26 | R8: 41605 | S8: 46261 | T8: 46261 | U8: --- | V8: =MIN(S8:U8) -> 46261 | W8: =MID(Q8,1,LEN(Q8)-3) -> NG | X8: =IFERROR(INDEX(AD:AD, MATCH(W8,AC:AC,0)),"---") -> NYMEX | Z8: как по дате соотносить | AC8: PA | AD8: NYMEX
A9: BR-10.26 | B9: BRV6 | C9: 46296 | D9: =MID(A9,1,SEARCH("-",A9,1)-1) -> BR | E9: BZ | F9: ="RUS:"&MID(B9,1,LEN(B9)-1)&"20"&RIGHT(A9,2)&"-"&INDEX(X:X, MATCH(J9,Q:Q,0))&":"&IF(N9="", MID(J9,1,LEN(J9)-2), N9&MID(J9,LEN(J9)-2,1))&"20"&RIGHT(J9,2) -> RUS:BRV2026-NYMEX:BZX2026 | G9: =MIN(C9,K9) -> 46295 | H9: =A9 -> BR-10.26 | I9: ="QR_"&IF(N9="", MID(J9,1,LEN(J9)-2)&RIGHT(J9),N9&MID(J9,LEN(J9)-2,1)&RIGHT(J9)) -> QR_BZX6 | J9: {=INDEX(Q:Q,MATCH(1, (W:W=E9)*(V:V>=C9-L9)*(V:V<=C9+L9), 0))} -> BZX26 | K9: =INDEX(V:V, MATCH(J9,Q:Q,0)) -> 46295 | L9: 10 | M9: =K9-C9 -> -1 | Q9: NGV26 | R9: 41605 | S9: 46293 | T9: 46293 | U9: --- | V9: =MIN(S9:U9) -> 46293 | W9: =MID(Q9,1,LEN(Q9)-3) -> NG | X9: =IFERROR(INDEX(AD:AD, MATCH(W9,AC:AC,0)),"---") -> NYMEX | AC9: PL | AD9: NYMEX
A10: BTC-3.26 | B10: BTH6 | C10: 46108 | D10: =MID(A10,1,SEARCH("-",A10,1)-1) -> BTC | E10: MBT | F10: ="RUS:"&MID(B10,1,LEN(B10)-1)&"20"&RIGHT(A10,2)&"-"&INDEX(X:X, MATCH(J10,Q:Q,0))&":"&IF(N10="", MID(J10,1,LEN(J10)-2), N10&MID(J10,LEN(J10)-2,1))&"20"&RIGHT(J10,2) -> RUS:BTH2026-CME:MBTH2026 | G10: =MIN(C10,K10) -> 46108 | H10: =A10 -> BTC-3.26 | I10: ="QR_"&IF(N10="", MID(J10,1,LEN(J10)-2)&RIGHT(J10),N10&MID(J10,LEN(J10)-2,1)&RIGHT(J10)) -> QR_MBTH6 | J10: {=INDEX(Q:Q,MATCH(1, (W:W=E10)*(V:V>=C10-L10)*(V:V<=C10+L10), 0))} -> MBTH26 | K10: =INDEX(V:V, MATCH(J10,Q:Q,0)) -> 46108 | L10: 10 | M10: =K10-C10 -> 0 | Q10: NGX26 | R10: 41605 | S10: 46323 | T10: 46323 | U10: --- | V10: =MIN(S10:U10) -> 46323 | W10: =MID(Q10,1,LEN(Q10)-3) -> NG | X10: =IFERROR(INDEX(AD:AD, MATCH(W10,AC:AC,0)),"---") -> NYMEX | AC10: SI | AD10: COMEX
A11: BTC-4.26 | B11: BTJ6 | C11: 46136 | D11: =MID(A11,1,SEARCH("-",A11,1)-1) -> BTC | E11: MBT | F11: ="RUS:"&MID(B11,1,LEN(B11)-1)&"20"&RIGHT(A11,2)&"-"&INDEX(X:X, MATCH(J11,Q:Q,0))&":"&IF(N11="", MID(J11,1,LEN(J11)-2), N11&MID(J11,LEN(J11)-2,1))&"20"&RIGHT(J11,2) -> RUS:BTJ2026-CME:MBTJ2026 | G11: =MIN(C11,K11) -> 46136 | H11: =A11 -> BTC-4.26 | I11: ="QR_"&IF(N11="", MID(J11,1,LEN(J11)-2)&RIGHT(J11),N11&MID(J11,LEN(J11)-2,1)&RIGHT(J11)) -> QR_MBTJ6 | J11: {=INDEX(Q:Q,MATCH(1, (W:W=E11)*(V:V>=C11-L11)*(V:V<=C11+L11), 0))} -> MBTJ26 | K11: =INDEX(V:V, MATCH(J11,Q:Q,0)) -> 46136 | L11: 10 | M11: =K11-C11 -> 0 | Q11: NGZ26 | R11: 41605 | S11: 46351 | T11: 46351 | U11: --- | V11: =MIN(S11:U11) -> 46351 | W11: =MID(Q11,1,LEN(Q11)-3) -> NG | X11: =IFERROR(INDEX(AD:AD, MATCH(W11,AC:AC,0)),"---") -> NYMEX | Z11: По месяцам подстановка | AC11: MGC | AD11: COMEX_MINI
A12: BTC-5.26 | B12: BTK6 | C12: 46171 | D12: =MID(A12,1,SEARCH("-",A12,1)-1) -> BTC | E12: MBT | F12: ="RUS:"&MID(B12,1,LEN(B12)-1)&"20"&RIGHT(A12,2)&"-"&INDEX(X:X, MATCH(J12,Q:Q,0))&":"&IF(N12="", MID(J12,1,LEN(J12)-2), N12&MID(J12,LEN(J12)-2,1))&"20"&RIGHT(J12,2) -> RUS:BTK2026-CME:MBTK2026 | G12: =MIN(C12,K12) -> 46171 | H12: =A12 -> BTC-5.26 | I12: ="QR_"&IF(N12="", MID(J12,1,LEN(J12)-2)&RIGHT(J12),N12&MID(J12,LEN(J12)-2,1)&RIGHT(J12)) -> QR_MBTK6 | J12: {=INDEX(Q:Q,MATCH(1, (W:W=E12)*(V:V>=C12-L12)*(V:V<=C12+L12), 0))} -> MBTK26 | K12: =INDEX(V:V, MATCH(J12,Q:Q,0)) -> 46171 | L12: 10 | M12: =K12-C12 -> 0 | Q12: NGF27 | R12: 41969 | S12: 46385 | T12: 46385 | U12: --- | V12: =MIN(S12:U12) -> 46385 | W12: =MID(Q12,1,LEN(Q12)-3) -> NG | X12: =IFERROR(INDEX(AD:AD, MATCH(W12,AC:AC,0)),"---") -> NYMEX | AC12: SIL | AD12: COMEX_MINI
A13: ED-3.26 | B13: EDH6 | C13: 46100 | D13: =MID(A13,1,SEARCH("-",A13,1)-1) -> ED | E13: EC | F13: ="RUS:"&MID(B13,1,LEN(B13)-1)&"20"&RIGHT(A13,2)&"-"&INDEX(X:X, MATCH(J13,Q:Q,0))&":"&IF(N13="", MID(J13,1,LEN(J13)-2), N13&MID(J13,LEN(J13)-2,1))&"20"&RIGHT(J13,2) -> RUS:EDH2026-CME:6EH2026 | G13: =MIN(C13,K13) -> 46097 | H13: =A13 -> ED-3.26 | I13: ="QR_"&IF(N13="", MID(J13,1,LEN(J13)-2)&RIGHT(J13),N13&MID(J13,LEN(J13)-2,1)&RIGHT(J13)) -> QR_6EH6 | J13: {=INDEX(Q:Q,MATCH(1, (W:W=E13)*(V:V>=C13-L13)*(V:V<=C13+L13), 0))} -> ECH26 | K13: =INDEX(V:V, MATCH(J13,Q:Q,0)) -> 46097 | L13: 10 | M13: =K13-C13 -> -3 | N13: 6E | Q13: NGG27 | R13: 41969 | S13: 46414 | T13: 46414 | U13: --- | V13: =MIN(S13:U13) -> 46414 | W13: =MID(Q13,1,LEN(Q13)-3) -> NG | X13: =IFERROR(INDEX(AD:AD, MATCH(W13,AC:AC,0)),"---") -> NYMEX | AC13: CNH | AD13: CME
A14: ED-6.26 | B14: EDM6 | C14: 46191 | D14: =MID(A14,1,SEARCH("-",A14,1)-1) -> ED | E14: EC | F14: ="RUS:"&MID(B14,1,LEN(B14)-1)&"20"&RIGHT(A14,2)&"-"&INDEX(X:X, MATCH(J14,Q:Q,0))&":"&IF(N14="", MID(J14,1,LEN(J14)-2), N14&MID(J14,LEN(J14)-2,1))&"20"&RIGHT(J14,2) -> RUS:EDM2026-CME:6EM2026 | G14: =MIN(C14,K14) -> 46188 | H14: =A14 -> ED-6.26 | I14: ="QR_"&IF(N14="", MID(J14,1,LEN(J14)-2)&RIGHT(J14),N14&MID(J14,LEN(J14)-2,1)&RIGHT(J14)) -> QR_6EM6 | J14: {=INDEX(Q:Q,MATCH(1, (W:W=E14)*(V:V>=C14-L14)*(V:V<=C14+L14), 0))} -> ECM26 | K14: =INDEX(V:V, MATCH(J14,Q:Q,0)) -> 46188 | L14: 10 | M14: =K14-C14 -> -3 | N14: 6E | Q14: NGH27 | R14: 41969 | S14: 46442 | T14: 46442 | U14: --- | V14: =MIN(S14:U14) -> 46442 | W14: =MID(Q14,1,LEN(Q14)-3) -> NG | X14: =IFERROR(INDEX(AD:AD, MATCH(W14,AC:AC,0)),"---") -> NYMEX | AC14: MES | AD14: CME_MINI
A15: ED-9.26 | B15: EDU6 | C15: 46282 | D15: =MID(A15,1,SEARCH("-",A15,1)-1) -> ED | E15: EC | F15: ="RUS:"&MID(B15,1,LEN(B15)-1)&"20"&RIGHT(A15,2)&"-"&INDEX(X:X, MATCH(J15,Q:Q,0))&":"&IF(N15="", MID(J15,1,LEN(J15)-2), N15&MID(J15,LEN(J15)-2,1))&"20"&RIGHT(J15,2) -> RUS:EDU2026-CME:6EU2026 | G15: =MIN(C15,K15) -> 46279 | H15: =A15 -> ED-9.26 | I15: ="QR_"&IF(N15="", MID(J15,1,LEN(J15)-2)&RIGHT(J15),N15&MID(J15,LEN(J15)-2,1)&RIGHT(J15)) -> QR_6EU6 | J15: {=INDEX(Q:Q,MATCH(1, (W:W=E15)*(V:V>=C15-L15)*(V:V<=C15+L15), 0))} -> ECU26 | K15: =INDEX(V:V, MATCH(J15,Q:Q,0)) -> 46279 | L15: 10 | M15: =K15-C15 -> -3 | N15: 6E | Q15: NGJ27 | R15: 41969 | S15: 46475 | T15: 46475 | U15: --- | V15: =MIN(S15:U15) -> 46475 | W15: =MID(Q15,1,LEN(Q15)-3) -> NG | X15: =IFERROR(INDEX(AD:AD, MATCH(W15,AC:AC,0)),"---") -> NYMEX | Z15: nasdaq etc | AC15: MNQ | AD15: CME_MINI
A16: ED-12.26 | B16: EDZ6 | C16: 46373 | D16: =MID(A16,1,SEARCH("-",A16,1)-1) -> ED | E16: EC | F16: ="RUS:"&MID(B16,1,LEN(B16)-1)&"20"&RIGHT(A16,2)&"-"&INDEX(X:X, MATCH(J16,Q:Q,0))&":"&IF(N16="", MID(J16,1,LEN(J16)-2), N16&MID(J16,LEN(J16)-2,1))&"20"&RIGHT(J16,2) -> RUS:EDZ2026-CME:6EZ2026 | G16: =MIN(C16,K16) -> 46370 | H16: =A16 -> ED-12.26 | I16: ="QR_"&IF(N16="", MID(J16,1,LEN(J16)-2)&RIGHT(J16),N16&MID(J16,LEN(J16)-2,1)&RIGHT(J16)) -> QR_6EZ6 | J16: {=INDEX(Q:Q,MATCH(1, (W:W=E16)*(V:V>=C16-L16)*(V:V<=C16+L16), 0))} -> ECZ26 | K16: =INDEX(V:V, MATCH(J16,Q:Q,0)) -> 46370 | L16: 10 | M16: =K16-C16 -> -3 | N16: 6E | Q16: NGK27 | R16: 41969 | S16: 46505 | T16: 46505 | U16: --- | V16: =MIN(S16:U16) -> 46505 | W16: =MID(Q16,1,LEN(Q16)-3) -> NG | X16: =IFERROR(INDEX(AD:AD, MATCH(W16,AC:AC,0)),"---") -> NYMEX | Z16: 6eu
A17: GOLD-3.26 | B17: GDH6 | C17: 46101 | D17: =MID(A17,1,SEARCH("-",A17,1)-1) -> GOLD | E17: GC | F17: ="RUS:"&MID(B17,1,LEN(B17)-1)&"20"&RIGHT(A17,2)&"-"&INDEX(X:X, MATCH(J17,Q:Q,0))&":"&IF(N17="", MID(J17,1,LEN(J17)-2), N17&MID(J17,LEN(J17)-2,1))&"20"&RIGHT(J17,2) -> RUS:GDH2026-COMEX:GCJ2026 | G17: =MIN(C17,K17) -> 46101 | H17: =A17 -> GOLD-3.26 | I17: ="QR_"&IF(N17="", MID(J17,1,LEN(J17)-2)&RIGHT(J17),N17&MID(J17,LEN(J17)-2,1)&RIGHT(J17)) -> QR_GCJ6 | J17: {=INDEX(Q:Q,MATCH(1, (W:W=E17)*(V:V>=C17-L17)*(V:V<=C17+L17), 0))} -> GCJ26 | K17: =INDEX(V:V, MATCH(J17,Q:Q,0)) -> 46112 | L17: 15 | M17: =K17-C17 -> 11 | Q17: NGM27 | R17: 41969 | S17: 46533 | T17: 46533 | U17: --- | V17: =MIN(S17:U17) -> 46533 | W17: =MID(Q17,1,LEN(Q17)-3) -> NG | X17: =IFERROR(INDEX(AD:AD, MATCH(W17,AC:AC,0)),"---") -> NYMEX
A18: GOLD-6.26 | B18: GDM6 | C18: 46192 | D18: =MID(A18,1,SEARCH("-",A18,1)-1) -> GOLD | E18: GC | F18: ="RUS:"&MID(B18,1,LEN(B18)-1)&"20"&RIGHT(A18,2)&"-"&INDEX(X:X, MATCH(J18,Q:Q,0))&":"&IF(N18="", MID(J18,1,LEN(J18)-2), N18&MID(J18,LEN(J18)-2,1))&"20"&RIGHT(J18,2) -> RUS:GDM2026-COMEX:GCN2026 | G18: =MIN(C18,K18) -> 46192 | H18: =A18 -> GOLD-6.26 | I18: ="QR_"&IF(N18="", MID(J18,1,LEN(J18)-2)&RIGHT(J18),N18&MID(J18,LEN(J18)-2,1)&RIGHT(J18)) -> QR_GCN6 | J18: {=INDEX(Q:Q,MATCH(1, (W:W=E18)*(V:V>=C18-L18)*(V:V<=C18+L18), 0))} -> GCN26 | K18: =INDEX(V:V, MATCH(J18,Q:Q,0)) -> 46203 | L18: 15 | M18: =K18-C18 -> 11 | Q18: NGN27 | R18: 41969 | S18: 46566 | T18: 46566 | U18: --- | V18: =MIN(S18:U18) -> 46566 | W18: =MID(Q18,1,LEN(Q18)-3) -> NG | X18: =IFERROR(INDEX(AD:AD, MATCH(W18,AC:AC,0)),"---") -> NYMEX
A19: GOLD-9.26 | B19: GDU6 | C19: 46283 | D19: =MID(A19,1,SEARCH("-",A19,1)-1) -> GOLD | E19: GC | F19: ="RUS:"&MID(B19,1,LEN(B19)-1)&"20"&RIGHT(A19,2)&"-"&INDEX(X:X, MATCH(J19,Q:Q,0))&":"&IF(N19="", MID(J19,1,LEN(J19)-2), N19&MID(J19,LEN(J19)-2,1))&"20"&RIGHT(J19,2) -> RUS:GDU2026-COMEX:GCV2026 | G19: =MIN(C19,K19) -> 46283 | H19: =A19 -> GOLD-9.26 | I19: ="QR_"&IF(N19="", MID(J19,1,LEN(J19)-2)&RIGHT(J19),N19&MID(J19,LEN(J19)-2,1)&RIGHT(J19)) -> QR_GCV6 | J19: {=INDEX(Q:Q,MATCH(1, (W:W=E19)*(V:V>=C19-L19)*(V:V<=C19+L19), 0))} -> GCV26 | K19: =INDEX(V:V, MATCH(J19,Q:Q,0)) -> 46295 | L19: 15 | M19: =K19-C19 -> 12 | Q19: NGQ27 | R19: 41969 | S19: 46596 | T19: 46596 | U19: --- | V19: =MIN(S19:U19) -> 46596 | W19: =MID(Q19,1,LEN(Q19)-3) -> NG | X19: =IFERROR(INDEX(AD:AD, MATCH(W19,AC:AC,0)),"---") -> NYMEX | Z19: nearest pairs x all
A20: GOLD-12.26 | B20: GDZ6 | C20: 46374 | D20: =MID(A20,1,SEARCH("-",A20,1)-1) -> GOLD | E20: GC | F20: ="RUS:"&MID(B20,1,LEN(B20)-1)&"20"&RIGHT(A20,2)&"-"&INDEX(X:X, MATCH(J20,Q:Q,0))&":"&IF(N20="", MID(J20,1,LEN(J20)-2), N20&MID(J20,LEN(J20)-2,1))&"20"&RIGHT(J20,2) -> RUS:GDZ2026-COMEX:GCF2027 | G20: =MIN(C20,K20) -> 46374 | H20: =A20 -> GOLD-12.26 | I20: ="QR_"&IF(N20="", MID(J20,1,LEN(J20)-2)&RIGHT(J20),N20&MID(J20,LEN(J20)-2,1)&RIGHT(J20)) -> QR_GCF7 | J20: {=INDEX(Q:Q,MATCH(1, (W:W=E20)*(V:V>=C20-L20)*(V:V<=C20+L20), 0))} -> GCF27 | K20: =INDEX(V:V, MATCH(J20,Q:Q,0)) -> 46387 | L20: 15 | M20: =K20-C20 -> 13 | Q20: NGU27 | R20: 41969 | S20: 46626 | T20: 46626 | U20: --- | V20: =MIN(S20:U20) -> 46626 | W20: =MID(Q20,1,LEN(Q20)-3) -> NG | X20: =IFERROR(INDEX(AD:AD, MATCH(W20,AC:AC,0)),"---") -> NYMEX
A21: NG-3.26 | B21: NGH6 | C21: 46108 | D21: =MID(A21,1,SEARCH("-",A21,1)-1) -> NG | E21: NG | F21: ="RUS:"&MID(B21,1,LEN(B21)-1)&"20"&RIGHT(A21,2)&"-"&INDEX(X:X, MATCH(J21,Q:Q,0))&":"&IF(N21="", MID(J21,1,LEN(J21)-2), N21&MID(J21,LEN(J21)-2,1))&"20"&RIGHT(J21,2) -> RUS:NGH2026-NYMEX:NGJ2026 | G21: =MIN(C21,K21) -> 46108 | H21: =A21 -> NG-3.26 | I21: ="QR_"&IF(N21="", MID(J21,1,LEN(J21)-2)&RIGHT(J21),N21&MID(J21,LEN(J21)-2,1)&RIGHT(J21)) -> QR_NGJ6 | J21: {=INDEX(Q:Q,MATCH(1, (W:W=E21)*(V:V>=C21-L21)*(V:V<=C21+L21), 0))} -> NGJ26 | K21: =INDEX(V:V, MATCH(J21,Q:Q,0)) -> 46108 | L21: 3 | M21: =K21-C21 -> 0 | Q21: NGV27 | R21: 41969 | S21: 46658 | T21: 46658 | U21: --- | V21: =MIN(S21:U21) -> 46658 | W21: =MID(Q21,1,LEN(Q21)-3) -> NG | X21: =IFERROR(INDEX(AD:AD, MATCH(W21,AC:AC,0)),"---") -> NYMEX
A22: NG-4.26 | B22: NGJ6 | C22: 46140 | D22: =MID(A22,1,SEARCH("-",A22,1)-1) -> NG | E22: NG | F22: ="RUS:"&MID(B22,1,LEN(B22)-1)&"20"&RIGHT(A22,2)&"-"&INDEX(X:X, MATCH(J22,Q:Q,0))&":"&IF(N22="", MID(J22,1,LEN(J22)-2), N22&MID(J22,LEN(J22)-2,1))&"20"&RIGHT(J22,2) -> RUS:NGJ2026-NYMEX:NGK2026 | G22: =MIN(C22,K22) -> 46140 | H22: =A22 -> NG-4.26 | I22: ="QR_"&IF(N22="", MID(J22,1,LEN(J22)-2)&RIGHT(J22),N22&MID(J22,LEN(J22)-2,1)&RIGHT(J22)) -> QR_NGK6 | J22: {=INDEX(Q:Q,MATCH(1, (W:W=E22)*(V:V>=C22-L22)*(V:V<=C22+L22), 0))} -> NGK26 | K22: =INDEX(V:V, MATCH(J22,Q:Q,0)) -> 46140 | L22: 3 | M22: =K22-C22 -> 0 | Q22: NGX27 | R22: 41969 | S22: 46687 | T22: 46687 | U22: --- | V22: =MIN(S22:U22) -> 46687 | W22: =MID(Q22,1,LEN(Q22)-3) -> NG | X22: =IFERROR(INDEX(AD:AD, MATCH(W22,AC:AC,0)),"---") -> NYMEX
A23: NG-5.26 | B23: NGK6 | C23: 46169 | D23: =MID(A23,1,SEARCH("-",A23,1)-1) -> NG | E23: NG | F23: ="RUS:"&MID(B23,1,LEN(B23)-1)&"20"&RIGHT(A23,2)&"-"&INDEX(X:X, MATCH(J23,Q:Q,0))&":"&IF(N23="", MID(J23,1,LEN(J23)-2), N23&MID(J23,LEN(J23)-2,1))&"20"&RIGHT(J23,2) -> RUS:NGK2026-NYMEX:NGM2026 | G23: =MIN(C23,K23) -> 46169 | H23: =A23 -> NG-5.26 | I23: ="QR_"&IF(N23="", MID(J23,1,LEN(J23)-2)&RIGHT(J23),N23&MID(J23,LEN(J23)-2,1)&RIGHT(J23)) -> QR_NGM6 | J23: {=INDEX(Q:Q,MATCH(1, (W:W=E23)*(V:V>=C23-L23)*(V:V<=C23+L23), 0))} -> NGM26 | K23: =INDEX(V:V, MATCH(J23,Q:Q,0)) -> 46169 | L23: 3 | M23: =K23-C23 -> 0 | Q23: NGZ27 | R23: 41969 | S23: 46717 | T23: 46717 | U23: --- | V23: =MIN(S23:U23) -> 46717 | W23: =MID(Q23,1,LEN(Q23)-3) -> NG | X23: =IFERROR(INDEX(AD:AD, MATCH(W23,AC:AC,0)),"---") -> NYMEX | Z23: базу данных мб на отдельный лист
A24: NG-6.26 | B24: NGM6 | C24: 46199 | D24: =MID(A24,1,SEARCH("-",A24,1)-1) -> NG | E24: NG | F24: ="RUS:"&MID(B24,1,LEN(B24)-1)&"20"&RIGHT(A24,2)&"-"&INDEX(X:X, MATCH(J24,Q:Q,0))&":"&IF(N24="", MID(J24,1,LEN(J24)-2), N24&MID(J24,LEN(J24)-2,1))&"20"&RIGHT(J24,2) -> RUS:NGM2026-NYMEX:NGN2026 | G24: =MIN(C24,K24) -> 46199 | H24: =A24 -> NG-6.26 | I24: ="QR_"&IF(N24="", MID(J24,1,LEN(J24)-2)&RIGHT(J24),N24&MID(J24,LEN(J24)-2,1)&RIGHT(J24)) -> QR_NGN6 | J24: {=INDEX(Q:Q,MATCH(1, (W:W=E24)*(V:V>=C24-L24)*(V:V<=C24+L24), 0))} -> NGN26 | K24: =INDEX(V:V, MATCH(J24,Q:Q,0)) -> 46199 | L24: 3 | M24: =K24-C24 -> 0 | Q24: NGF28 | R24: 42335 | S24: 46750 | T24: 46750 | U24: --- | V24: =MIN(S24:U24) -> 46750 | W24: =MID(Q24,1,LEN(Q24)-3) -> NG | X24: =IFERROR(INDEX(AD:AD, MATCH(W24,AC:AC,0)),"---") -> NYMEX | Z24: макрос для всех комбинаций - но продумать логику
A25: NG-7.26 | B25: NGN6 | C25: 46232 | D25: =MID(A25,1,SEARCH("-",A25,1)-1) -> NG | E25: NG | F25: ="RUS:"&MID(B25,1,LEN(B25)-1)&"20"&RIGHT(A25,2)&"-"&INDEX(X:X, MATCH(J25,Q:Q,0))&":"&IF(N25="", MID(J25,1,LEN(J25)-2), N25&MID(J25,LEN(J25)-2,1))&"20"&RIGHT(J25,2) -> RUS:NGN2026-NYMEX:NGQ2026 | G25: =MIN(C25,K25) -> 46232 | H25: =A25 -> NG-7.26 | I25: ="QR_"&IF(N25="", MID(J25,1,LEN(J25)-2)&RIGHT(J25),N25&MID(J25,LEN(J25)-2,1)&RIGHT(J25)) -> QR_NGQ6 | J25: {=INDEX(Q:Q,MATCH(1, (W:W=E25)*(V:V>=C25-L25)*(V:V<=C25+L25), 0))} -> NGQ26 | K25: =INDEX(V:V, MATCH(J25,Q:Q,0)) -> 46232 | L25: 3 | M25: =K25-C25 -> 0 | Q25: NGG28 | R25: 42335 | S25: 46779 | T25: 46779 | U25: --- | V25: =MIN(S25:U25) -> 46779 | W25: =MID(Q25,1,LEN(Q25)-3) -> NG | X25: =IFERROR(INDEX(AD:AD, MATCH(W25,AC:AC,0)),"---") -> NYMEX
A26: NG-8.26 | B26: NGQ6 | C26: 46261 | D26: =MID(A26,1,SEARCH("-",A26,1)-1) -> NG | E26: NG | F26: ="RUS:"&MID(B26,1,LEN(B26)-1)&"20"&RIGHT(A26,2)&"-"&INDEX(X:X, MATCH(J26,Q:Q,0))&":"&IF(N26="", MID(J26,1,LEN(J26)-2), N26&MID(J26,LEN(J26)-2,1))&"20"&RIGHT(J26,2) -> RUS:NGQ2026-NYMEX:NGU2026 | G26: =MIN(C26,K26) -> 46261 | H26: =A26 -> NG-8.26 | I26: ="QR_"&IF(N26="", MID(J26,1,LEN(J26)-2)&RIGHT(J26),N26&MID(J26,LEN(J26)-2,1)&RIGHT(J26)) -> QR_NGU6 | J26: {=INDEX(Q:Q,MATCH(1, (W:W=E26)*(V:V>=C26-L26)*(V:V<=C26+L26), 0))} -> NGU26 | K26: =INDEX(V:V, MATCH(J26,Q:Q,0)) -> 46261 | L26: 3 | M26: =K26-C26 -> 0 | Q26: NGH28 | R26: 42335 | S26: 46808 | T26: 46808 | U26: --- | V26: =MIN(S26:U26) -> 46808 | W26: =MID(Q26,1,LEN(Q26)-3) -> NG | X26: =IFERROR(INDEX(AD:AD, MATCH(W26,AC:AC,0)),"---") -> NYMEX
A27: NG-9.26 | B27: NGU6 | C27: 46293 | D27: =MID(A27,1,SEARCH("-",A27,1)-1) -> NG | E27: NG | F27: ="RUS:"&MID(B27,1,LEN(B27)-1)&"20"&RIGHT(A27,2)&"-"&INDEX(X:X, MATCH(J27,Q:Q,0))&":"&IF(N27="", MID(J27,1,LEN(J27)-2), N27&MID(J27,LEN(J27)-2,1))&"20"&RIGHT(J27,2) -> RUS:NGU2026-NYMEX:NGV2026 | G27: =MIN(C27,K27) -> 46293 | H27: =A27 -> NG-9.26 | I27: ="QR_"&IF(N27="", MID(J27,1,LEN(J27)-2)&RIGHT(J27),N27&MID(J27,LEN(J27)-2,1)&RIGHT(J27)) -> QR_NGV6 | J27: {=INDEX(Q:Q,MATCH(1, (W:W=E27)*(V:V>=C27-L27)*(V:V<=C27+L27), 0))} -> NGV26 | K27: =INDEX(V:V, MATCH(J27,Q:Q,0)) -> 46293 | L27: 3 | M27: =K27-C27 -> 0 | Q27: NGJ28 | R27: 42335 | S27: 46841 | T27: 46841 | U27: --- | V27: =MIN(S27:U27) -> 46841 | W27: =MID(Q27,1,LEN(Q27)-3) -> NG | X27: =IFERROR(INDEX(AD:AD, MATCH(W27,AC:AC,0)),"---") -> NYMEX
A28: PLD-3.26 | B28: PDH6 | C28: 46101 | D28: =MID(A28,1,SEARCH("-",A28,1)-1) -> PLD | E28: PA | F28: ="RUS:"&MID(B28,1,LEN(B28)-1)&"20"&RIGHT(A28,2)&"-"&INDEX(X:X, MATCH(J28,Q:Q,0))&":"&IF(N28="", MID(J28,1,LEN(J28)-2), N28&MID(J28,LEN(J28)-2,1))&"20"&RIGHT(J28,2) -> RUS:PDH2026-NYMEX:PAJ2026 | G28: =MIN(C28,K28) -> 46101 | H28: =A28 -> PLD-3.26 | I28: ="QR_"&IF(N28="", MID(J28,1,LEN(J28)-2)&RIGHT(J28),N28&MID(J28,LEN(J28)-2,1)&RIGHT(J28)) -> QR_PAJ6 | J28: {=INDEX(Q:Q,MATCH(1, (W:W=E28)*(V:V>=C28-L28)*(V:V<=C28+L28), 0))} -> PAJ26 | K28: =INDEX(V:V, MATCH(J28,Q:Q,0)) -> 46112 | L28: 15 | M28: =K28-C28 -> 11 | Q28: NGK28 | R28: 42335 | S28: 46869 | T28: 46869 | U28: --- | V28: =MIN(S28:U28) -> 46869 | W28: =MID(Q28,1,LEN(Q28)-3) -> NG | X28: =IFERROR(INDEX(AD:AD, MATCH(W28,AC:AC,0)),"---") -> NYMEX
A29: PLD-6.26 | B29: PDM6 | C29: 46192 | D29: =MID(A29,1,SEARCH("-",A29,1)-1) -> PLD | E29: PA | F29: ="RUS:"&MID(B29,1,LEN(B29)-1)&"20"&RIGHT(A29,2)&"-"&INDEX(X:X, MATCH(J29,Q:Q,0))&":"&IF(N29="", MID(J29,1,LEN(J29)-2), N29&MID(J29,LEN(J29)-2,1))&"20"&RIGHT(J29,2) -> RUS:PDM2026-NYMEX:PAM2026 | G29: =MIN(C29,K29) -> 46171 | H29: =A29 -> PLD-6.26 | I29: ="QR_"&IF(N29="", MID(J29,1,LEN(J29)-2)&RIGHT(J29),N29&MID(J29,LEN(J29)-2,1)&RIGHT(J29)) -> QR_PAM6 | J29: {=INDEX(Q:Q,MATCH(1, (W:W=E29)*(V:V>=C29-L29)*(V:V<=C29+L29), 0))} -> PAM26 | K29: =INDEX(V:V, MATCH(J29,Q:Q,0)) -> 46171 | L29: 30 | M29: =K29-C29 -> -21 | Q29: NGM28 | R29: 42335 | S29: 46899 | T29: 46899 | U29: --- | V29: =MIN(S29:U29) -> 46899 | W29: =MID(Q29,1,LEN(Q29)-3) -> NG | X29: =IFERROR(INDEX(AD:AD, MATCH(W29,AC:AC,0)),"---") -> NYMEX
A30: PLD-9.26 | B30: PDU6 | C30: 46283 | D30: =MID(A30,1,SEARCH("-",A30,1)-1) -> PLD | E30: PA | F30: ="RUS:"&MID(B30,1,LEN(B30)-1)&"20"&RIGHT(A30,2)&"-"&INDEX(X:X, MATCH(J30,Q:Q,0))&":"&IF(N30="", MID(J30,1,LEN(J30)-2), N30&MID(J30,LEN(J30)-2,1))&"20"&RIGHT(J30,2) -> RUS:PDU2026-NYMEX:PAU2026 | G30: =MIN(C30,K30) -> 46265 | H30: =A30 -> PLD-9.26 | I30: ="QR_"&IF(N30="", MID(J30,1,LEN(J30)-2)&RIGHT(J30),N30&MID(J30,LEN(J30)-2,1)&RIGHT(J30)) -> QR_PAU6 | J30: {=INDEX(Q:Q,MATCH(1, (W:W=E30)*(V:V>=C30-L30)*(V:V<=C30+L30), 0))} -> PAU26 | K30: =INDEX(V:V, MATCH(J30,Q:Q,0)) -> 46265 | L30: 30 | M30: =K30-C30 -> -18 | Q30: NGN28 | R30: 42335 | S30: 46932 | T30: 46932 | U30: --- | V30: =MIN(S30:U30) -> 46932 | W30: =MID(Q30,1,LEN(Q30)-3) -> NG | X30: =IFERROR(INDEX(AD:AD, MATCH(W30,AC:AC,0)),"---") -> NYMEX
A31: PLD-12.26 | B31: PDZ6 | C31: 46374 | D31: =MID(A31,1,SEARCH("-",A31,1)-1) -> PLD | E31: PA | F31: ="RUS:"&MID(B31,1,LEN(B31)-1)&"20"&RIGHT(A31,2)&"-"&INDEX(X:X, MATCH(J31,Q:Q,0))&":"&IF(N31="", MID(J31,1,LEN(J31)-2), N31&MID(J31,LEN(J31)-2,1))&"20"&RIGHT(J31,2) -> RUS:PDZ2026-NYMEX:PAZ2026 | G31: =MIN(C31,K31) -> 46356 | H31: =A31 -> PLD-12.26 | I31: ="QR_"&IF(N31="", MID(J31,1,LEN(J31)-2)&RIGHT(J31),N31&MID(J31,LEN(J31)-2,1)&RIGHT(J31)) -> QR_PAZ6 | J31: {=INDEX(Q:Q,MATCH(1, (W:W=E31)*(V:V>=C31-L31)*(V:V<=C31+L31), 0))} -> PAZ26 | K31: =INDEX(V:V, MATCH(J31,Q:Q,0)) -> 46356 | L31: 30 | M31: =K31-C31 -> -18 | Q31: NGQ28 | R31: 42335 | S31: 46961 | T31: 46961 | U31: --- | V31: =MIN(S31:U31) -> 46961 | W31: =MID(Q31,1,LEN(Q31)-3) -> NG | X31: =IFERROR(INDEX(AD:AD, MATCH(W31,AC:AC,0)),"---") -> NYMEX
A32: PLT-3.26 | B32: PTH6 | C32: 46101 | D32: =MID(A32,1,SEARCH("-",A32,1)-1) -> PLT | E32: PL | F32: ="RUS:"&MID(B32,1,LEN(B32)-1)&"20"&RIGHT(A32,2)&"-"&INDEX(X:X, MATCH(J32,Q:Q,0))&":"&IF(N32="", MID(J32,1,LEN(J32)-2), N32&MID(J32,LEN(J32)-2,1))&"20"&RIGHT(J32,2) -> RUS:PTH2026-NYMEX:PLJ2026 | G32: =MIN(C32,K32) -> 46101 | H32: =A32 -> PLT-3.26 | I32: ="QR_"&IF(N32="", MID(J32,1,LEN(J32)-2)&RIGHT(J32),N32&MID(J32,LEN(J32)-2,1)&RIGHT(J32)) -> QR_PLJ6 | J32: {=INDEX(Q:Q,MATCH(1, (W:W=E32)*(V:V>=C32-L32)*(V:V<=C32+L32), 0))} -> PLJ26 | K32: =INDEX(V:V, MATCH(J32,Q:Q,0)) -> 46112 | L32: 15 | M32: =K32-C32 -> 11 | Q32: NGU28 | R32: 42335 | S32: 46994 | T32: 46994 | U32: --- | V32: =MIN(S32:U32) -> 46994 | W32: =MID(Q32,1,LEN(Q32)-3) -> NG | X32: =IFERROR(INDEX(AD:AD, MATCH(W32,AC:AC,0)),"---") -> NYMEX
A33: PLT-6.26 | B33: PTM6 | C33: 46192 | D33: =MID(A33,1,SEARCH("-",A33,1)-1) -> PLT | E33: PL | F33: ="RUS:"&MID(B33,1,LEN(B33)-1)&"20"&RIGHT(A33,2)&"-"&INDEX(X:X, MATCH(J33,Q:Q,0))&":"&IF(N33="", MID(J33,1,LEN(J33)-2), N33&MID(J33,LEN(J33)-2,1))&"20"&RIGHT(J33,2) -> RUS:PTM2026-NYMEX:PLN2026 | G33: =MIN(C33,K33) -> 46192 | H33: =A33 -> PLT-6.26 | I33: ="QR_"&IF(N33="", MID(J33,1,LEN(J33)-2)&RIGHT(J33),N33&MID(J33,LEN(J33)-2,1)&RIGHT(J33)) -> QR_PLN6 | J33: {=INDEX(Q:Q,MATCH(1, (W:W=E33)*(V:V>=C33-L33)*(V:V<=C33+L33), 0))} -> PLN26 | K33: =INDEX(V:V, MATCH(J33,Q:Q,0)) -> 46203 | L33: 15 | M33: =K33-C33 -> 11 | Q33: NGV28 | R33: 42335 | S33: 47023 | T33: 47023 | U33: --- | V33: =MIN(S33:U33) -> 47023 | W33: =MID(Q33,1,LEN(Q33)-3) -> NG | X33: =IFERROR(INDEX(AD:AD, MATCH(W33,AC:AC,0)),"---") -> NYMEX
A34: PLT-9.26 | B34: PTU6 | C34: 46283 | D34: =MID(A34,1,SEARCH("-",A34,1)-1) -> PLT | E34: PL | F34: ="RUS:"&MID(B34,1,LEN(B34)-1)&"20"&RIGHT(A34,2)&"-"&INDEX(X:X, MATCH(J34,Q:Q,0))&":"&IF(N34="", MID(J34,1,LEN(J34)-2), N34&MID(J34,LEN(J34)-2,1))&"20"&RIGHT(J34,2) -> RUS:PTU2026-NYMEX:PLV2026 | G34: =MIN(C34,K34) -> 46283 | H34: =A34 -> PLT-9.26 | I34: ="QR_"&IF(N34="", MID(J34,1,LEN(J34)-2)&RIGHT(J34),N34&MID(J34,LEN(J34)-2,1)&RIGHT(J34)) -> QR_PLV6 | J34: {=INDEX(Q:Q,MATCH(1, (W:W=E34)*(V:V>=C34-L34)*(V:V<=C34+L34), 0))} -> PLV26 | K34: =INDEX(V:V, MATCH(J34,Q:Q,0)) -> 46295 | L34: 15 | M34: =K34-C34 -> 12 | Q34: NGX28 | R34: 42335 | S34: 47053 | T34: 47053 | U34: --- | V34: =MIN(S34:U34) -> 47053 | W34: =MID(Q34,1,LEN(Q34)-3) -> NG | X34: =IFERROR(INDEX(AD:AD, MATCH(W34,AC:AC,0)),"---") -> NYMEX
A35: PLT-12.26 | B35: PTZ6 | C35: 46374 | D35: =MID(A35,1,SEARCH("-",A35,1)-1) -> PLT | E35: PL | F35: ="RUS:"&MID(B35,1,LEN(B35)-1)&"20"&RIGHT(A35,2)&"-"&INDEX(X:X, MATCH(J35,Q:Q,0))&":"&IF(N35="", MID(J35,1,LEN(J35)-2), N35&MID(J35,LEN(J35)-2,1))&"20"&RIGHT(J35,2) -> RUS:PTZ2026-NYMEX:PLF2027 | G35: =MIN(C35,K35) -> 46374 | H35: =A35 -> PLT-12.26 | I35: ="QR_"&IF(N35="", MID(J35,1,LEN(J35)-2)&RIGHT(J35),N35&MID(J35,LEN(J35)-2,1)&RIGHT(J35)) -> QR_PLF7 | J35: {=INDEX(Q:Q,MATCH(1, (W:W=E35)*(V:V>=C35-L35)*(V:V<=C35+L35), 0))} -> PLF27 | K35: =INDEX(V:V, MATCH(J35,Q:Q,0)) -> 46387 | L35: 15 | M35: =K35-C35 -> 13 | Q35: NGZ28 | R35: 42335 | S35: 47085 | T35: 47085 | U35: --- | V35: =MIN(S35:U35) -> 47085 | W35: =MID(Q35,1,LEN(Q35)-3) -> NG | X35: =IFERROR(INDEX(AD:AD, MATCH(W35,AC:AC,0)),"---") -> NYMEX
A36: SILV-3.26 | B36: SVH6 | C36: 46101 | D36: =MID(A36,1,SEARCH("-",A36,1)-1) -> SILV | E36: SI | F36: ="RUS:"&MID(B36,1,LEN(B36)-1)&"20"&RIGHT(A36,2)&"-"&INDEX(X:X, MATCH(J36,Q:Q,0))&":"&IF(N36="", MID(J36,1,LEN(J36)-2), N36&MID(J36,LEN(J36)-2,1))&"20"&RIGHT(J36,2) -> RUS:SVH2026-COMEX:SIJ2026 | G36: =MIN(C36,K36) -> 46101 | H36: =A36 -> SILV-3.26 | I36: ="QR_"&IF(N36="", MID(J36,1,LEN(J36)-2)&RIGHT(J36),N36&MID(J36,LEN(J36)-2,1)&RIGHT(J36)) -> QR_SIJ6 | J36: {=INDEX(Q:Q,MATCH(1, (W:W=E36)*(V:V>=C36-L36)*(V:V<=C36+L36), 0))} -> SIJ26 | K36: =INDEX(V:V, MATCH(J36,Q:Q,0)) -> 46112 | L36: 15 | M36: =K36-C36 -> 11 | Q36: NGF29 | R36: 42703 | S36: 47114 | T36: 47114 | U36: --- | V36: =MIN(S36:U36) -> 47114 | W36: =MID(Q36,1,LEN(Q36)-3) -> NG | X36: =IFERROR(INDEX(AD:AD, MATCH(W36,AC:AC,0)),"---") -> NYMEX
... A46: SILV-9.26 | B46: SVU6 | C46: 46283 | D46: =MID(A46,1,SEARCH("-",A46,1)-1) -> SILV | E46: SIL | F46: ="RUS:"&MID(B46,1,LEN(B46)-1)&"20"&RIGHT(A46,2)&"-"&INDEX(X:X, MATCH(J46,Q:Q,0))&":"&IF(N46="", MID(J46,1,LEN(J46)-2), N46&MID(J46,LEN(J46)-2,1))&"20"&RIGHT(J46,2) -> RUS:SVU2026-COMEX_MINI:SILU2026 | G46: =MIN(C46,K46) -> 46265 | H46: =A46 -> SILV-9.26 | I46: ="QR_"&IF(N46="", MID(J46,1,LEN(J46)-2)&RIGHT(J46),N46&MID(J46,LEN(J46)-2,1)&RIGHT(J46)) -> QR_SILU6 | J46: {=INDEX(Q:Q,MATCH(1, (W:W=E46)*(V:V>=C46-L46)*(V:V<=C46+L46), 0))} -> SILU26 | K46: =INDEX(V:V, MATCH(J46,Q:Q,0)) -> 46265 | L46: 30 | M46: =K46-C46 -> -18 | Q46: NGX29 | R46: 42703 | S46: 47420 | T46: 47420 | U46: --- | V46: =MIN(S46:U46) -> 47420 | W46: =MID(Q46,1,LEN(Q46)-3) -> NG | X46: =IFERROR(INDEX(AD:AD, MATCH(W46,AC:AC,0)),"---") -> NYMEX
A47: UCNY-3.26 | B47: UCH6 | C47: 46100 | D47: =MID(A47,1,SEARCH("-",A47,1)-1) -> UCNY | E47: CNH | F47: ="RUS:"&MID(B47,1,LEN(B47)-1)&"20"&RIGHT(A47,2)&"-"&INDEX(X:X, MATCH(J47,Q:Q,0))&":"&IF(N47="", MID(J47,1,LEN(J47)-2), N47&MID(J47,LEN(J47)-2,1))&"20"&RIGHT(J47,2) -> RUS:UCH2026-CME:UCH2026 | G47: =MIN(C47,K47) -> 46097 | H47: =A47 -> UCNY-3.26 | I47: ="QR_"&IF(N47="", MID(J47,1,LEN(J47)-2)&RIGHT(J47),N47&MID(J47,LEN(J47)-2,1)&RIGHT(J47)) -> QR_UCH6 | J47: {=INDEX(Q:Q,MATCH(1, (W:W=E47)*(V:V>=C47-L47)*(V:V<=C47+L47), 0))} -> CNHH26 | K47: =INDEX(V:V, MATCH(J47,Q:Q,0)) -> 46097 | L47: 15 | M47: =K47-C47 -> -3 | N47: UC | Q47: NGZ29 | R47: 42703 | S47: 47450 | T47: 47450 | U47: --- | V47: =MIN(S47:U47) -> 47450 | W47: =MID(Q47,1,LEN(Q47)-3) -> NG | X47: =IFERROR(INDEX(AD:AD, MATCH(W47,AC:AC,0)),"---") -> NYMEX
A48: UCNY-6.26 | B48: UCM6 | C48: 46191 | D48: =MID(A48,1,SEARCH("-",A48,1)-1) -> UCNY | E48: CNH | F48: ="RUS:"&MID(B48,1,LEN(B48)-1)&"20"&RIGHT(A48,2)&"-"&INDEX(X:X, MATCH(J48,Q:Q,0))&":"&IF(N48="", MID(J48,1,LEN(J48)-2), N48&MID(J48,LEN(J48)-2,1))&"20"&RIGHT(J48,2) -> RUS:UCM2026-CME:UCM2026 | G48: =MIN(C48,K48) -> 46188 | H48: =A48 -> UCNY-6.26 | I48: ="QR_"&IF(N48="", MID(J48,1,LEN(J48)-2)&RIGHT(J48),N48&MID(J48,LEN(J48)-2,1)&RIGHT(J48)) -> QR_UCM6 | J48: {=INDEX(Q:Q,MATCH(1, (W:W=E48)*(V:V>=C48-L48)*(V:V<=C48+L48), 0))} -> CNHM26 | K48: =INDEX(V:V, MATCH(J48,Q:Q,0)) -> 46188 | L48: 15 | M48: =K48-C48 -> -3 | N48: UC | Q48: NGF30 | R48: 43068 | S48: 47479 | T48: 47479 | U48: --- | V48: =MIN(S48:U48) -> 47479 | W48: =MID(Q48,1,LEN(Q48)-3) -> NG | X48: =IFERROR(INDEX(AD:AD, MATCH(W48,AC:AC,0)),"---") -> NYMEX
A49: UCNY-9.26 | B49: UCU6 | C49: 46282 | D49: =MID(A49,1,SEARCH("-",A49,1)-1) -> UCNY | E49: CNH | F49: ="RUS:"&MID(B49,1,LEN(B49)-1)&"20"&RIGHT(A49,2)&"-"&INDEX(X:X, MATCH(J49,Q:Q,0))&":"&IF(N49="", MID(J49,1,LEN(J49)-2), N49&MID(J49,LEN(J49)-2,1))&"20"&RIGHT(J49,2) -> RUS:UCU2026-CME:UCU2026 | G49: =MIN(C49,K49) -> 46279 | H49: =A49 -> UCNY-9.26 | I49: ="QR_"&IF(N49="", MID(J49,1,LEN(J49)-2)&RIGHT(J49),N49&MID(J49,LEN(J49)-2,1)&RIGHT(J49)) -> QR_UCU6 | J49: {=INDEX(Q:Q,MATCH(1, (W:W=E49)*(V:V>=C49-L49)*(V:V<=C49+L49), 0))} -> CNHU26 | K49: =INDEX(V:V, MATCH(J49,Q:Q,0)) -> 46279 | L49: 15 | M49: =K49-C49 -> -3 | N49: UC | Q49: NGG30 | R49: 43068 | S49: 47512 | T49: 47512 | U49: --- | V49: =MIN(S49:U49) -> 47512 | W49: =MID(Q49,1,LEN(Q49)-3) -> NG | X49: =IFERROR(INDEX(AD:AD, MATCH(W49,AC:AC,0)),"---") -> NYMEX
...

Sheet AComb
A1: Instrument 1 | B1: Exp 1 | C1: Instrument 2 | D1: Exp 2 | E1: Final Exp | F1: Symbol Search
A2: BR-4.26 / BZ | B2: 46113 | C2: BZK26 | D2: 46112
A3: BR-5.26 / BZ | B3: 46146 | C3: BZM26 | D3: 46142
A4: BR-6.26 / BZ | B4: 46174 | C4: BZN26 | D4: 46171
A5: BR-7.26 / BZ | B5: 46204 | C5: BZQ26 | D5: 46203
A6: BR-8.26 / BZ | B6: 46237 | C6: BZU26 | D6: 46234
A7: BR-9.26 / BZ | B7: 46265 | C7: BZV26 | D7: 46262
A8: BR-10.26 / BZ | B8: 46296 | C8: BZX26 | D8: 46295
A9: BTC-3.26 / MBT | B9: 46108 | C9: MBTH26 | D9: 46108
A10: BTC-4.26 / MBT | B10: 46136 | C10: MBTJ26 | D10: 46136
A11: BTC-5.26 / MBT | B11: 46171 | C11: MBTK26 | D11: 46171
A12: ED-3.26 / EC | B12: 46100 | C12: ECH26 | D12: 46097
A13: ED-6.26 / EC | B13: 46191 | C13: ECH26 | D13: 46097
C14: ECJ26 | D14: 46125
C15: ECK26 | D15: 46160
C16: ECM26 | D16: 46188
A17: ED-9.26 / EC | B17: 46282 | C17: ECM26 | D17: 46188
C18: ECN26 | D18: 46216
C19: ECQ26 | D19: 46251
C20: ECU26 | D20: 46279
A21: ED-12.26 / EC | B21: 46373 | C21: ECU26 | D21: 46279
C22: ECZ26 | D22: 46370
A23: GOLD-3.26 / GC | B23: 46101 | C23: --- | D23: ---
A24: GOLD-6.26 / GC | B24: 46192 | C24: GCJ26 | D24: 46112
C25: GCK26 | D25: 46142
C26: GCM26 | D26: 46171
A27: GOLD-9.26 / GC | B27: 46283 | C27: GCN26 | D27: 46203
C28: GCQ26 | D28: 46234
C29: GCU26 | D29: 46265
A30: GOLD-12.26 / GC | B30: 46374 | C30: GCV26 | D30: 46295
C31: GCX26 | D31: 46325
C32: GCZ26 | D32: 46356
A33: NG-3.26 / NG | B33: 46108 | C33: NGJ26 | D33: 46108
A34: NG-4.26 / NG | B34: 46140 | C34: NGK26 | D34: 46140
A35: NG-5.26 / NG | B35: 46169 | C35: NGM26 | D35: 46169
A36: NG-6.26 / NG | B36: 46199 | C36: NGN26 | D36: 46199
A37: NG-7.26 / NG | B37: 46232 | C37: NGQ26 | D37: 46232
A38: NG-8.26 / NG | B38: 46261 | C38: NGU26 | D38: 46261
A39: NG-9.26 / NG | B39: 46293 | C39: NGV26 | D39: 46293
A40: PLD-3.26 / PA | B40: 46101 | C40: --- | D40: ---
...

Sheet Backup
A2: Инструмент 1 | B2: Код инструмента 1 | C2: Погашение 1 | D2: Underl MOEX | E2: Underl CME | F2: Spread for TView | G2: Final Date of Spread | H2: Robot 1 leg | I2: Robot 2 leg | J2: Инструмент 2 | K2: Exp Date 2 | L2: Date corr | M2: Date Diff | P2: Product Code | Q2: First Trade | R2: Last Trade | S2: Settlement | T2: FND | U2: Final Date | V2: Underl CME | W2: Exch | Y2: constructor own | AB2: Underl2 | AC2: Exch
A3: BR-4.26 | B3: BRJ6 | C3: 46113 | D3: =MID(A3,1,SEARCH("-",A3,1)-1) -> BR | E3: BZ | F3: ="RUS:"&MID(B3,1,LEN(B3)-1)&"20"&RIGHT(A3,2)&"-"&INDEX(W:W, MATCH(J3,P:P,0))&":"&MID(J3,1,LEN(J3)-2)&"20"&RIGHT(J3,2) -> RUS:BRJ2026-NYMEX:BZK2026 | G3: =MIN(C3,K3) -> 46112 | H3: =A3 -> BR-4.26 | I3: =J3 -> BZK26 | J3: {=INDEX(P:P,MATCH(1, (V:V=E3)*(U:U>=C3-L3)*(U:U<=C3+L3), 0))} -> BZK26 | K3: =INDEX(U:U, MATCH(J3,P:P,0)) -> 46112 | L3: 10 | M3: =K3-C3 -> -1 | P3: NGJ26 | Q3: 41605 | R3: 46108 | S3: 46108 | T3: --- | U3: =MIN(R3:T3) -> 46108 | V3: =MID(P3,1,LEN(P3)-3) -> NG | W3: =IFERROR(INDEX(AC:AC, MATCH(V3,AB:AB,0)),"---") -> NYMEX | AB3: BZ | AC3: NYMEX
A4: BR-5.26 | B4: BRK6 | C4: 46146 | D4: =MID(A4,1,SEARCH("-",A4,1)-1) -> BR | E4: BZ | F4: ="RUS:"&MID(B4,1,LEN(B4)-1)&"20"&RIGHT(A4,2)&"-"&INDEX(W:W, MATCH(J4,P:P,0))&":"&MID(J4,1,LEN(J4)-2)&"20"&RIGHT(J4,2) -> RUS:BRK2026-NYMEX:BZM2026 | G4: =MIN(C4,K4) -> 46142 | H4: =A4 -> BR-5.26 | I4: =J4 -> BZM26 | J4: {=INDEX(P:P,MATCH(1, (V:V=E4)*(U:U>=C4-L4)*(U:U<=C4+L4), 0))} -> BZM26 | K4: =INDEX(U:U, MATCH(J4,P:P,0)) -> 46142 | L4: 10 | M4: =K4-C4 -> -4 | P4: NGK26 | Q4: 41605 | R4: 46140 | S4: 46140 | T4: --- | U4: =MIN(R4:T4) -> 46140 | V4: =MID(P4,1,LEN(P4)-3) -> NG | W4: =IFERROR(INDEX(AC:AC, MATCH(V4,AB:AB,0)),"---") -> NYMEX | Y4: consrt robot | AB4: MBT | AC4: CME
A5: BR-6.26 | B5: BRM6 | C5: 46174 | D5: =MID(A5,1,SEARCH("-",A5,1)-1) -> BR | E5: BZ | F5: ="RUS:"&MID(B5,1,LEN(B5)-1)&"20"&RIGHT(A5,2)&"-"&INDEX(W:W, MATCH(J5,P:P,0))&":"&MID(J5,1,LEN(J5)-2)&"20"&RIGHT(J5,2) -> RUS:BRM2026-NYMEX:BZN2026 | G5: =MIN(C5,K5) -> 46171 | H5: =A5 -> BR-6.26 | I5: =J5 -> BZN26 | J5: {=INDEX(P:P,MATCH(1, (V:V=E5)*(U:U>=C5-L5)*(U:U<=C5+L5), 0))} -> BZN26 | K5: =INDEX(U:U, MATCH(J5,P:P,0)) -> 46171 | L5: 10 | M5: =K5-C5 -> -3 | P5: NGM26 | Q5: 41605 | R5: 46169 | S5: 46169 | T5: --- | U5: =MIN(R5:T5) -> 46169 | V5: =MID(P5,1,LEN(P5)-3) -> NG | W5: =IFERROR(INDEX(AC:AC, MATCH(V5,AB:AB,0)),"---") -> NYMEX | Y5: constr tview | AB5: EC | AC5: CME
A6: BR-7.26 | B6: BRN6 | C6: 46204 | D6: =MID(A6,1,SEARCH("-",A6,1)-1) -> BR | E6: BZ | F6: ="RUS:"&MID(B6,1,LEN(B6)-1)&"20"&RIGHT(A6,2)&"-"&INDEX(W:W, MATCH(J6,P:P,0))&":"&MID(J6,1,LEN(J6)-2)&"20"&RIGHT(J6,2) -> RUS:BRN2026-NYMEX:BZQ2026 | G6: =MIN(C6,K6) -> 46203 | H6: =A6 -> BR-7.26 | I6: =J6 -> BZQ26 | J6: {=INDEX(P:P,MATCH(1, (V:V=E6)*(U:U>=C6-L6)*(U:U<=C6+L6), 0))} -> BZQ26 | K6: =INDEX(U:U, MATCH(J6,P:P,0)) -> 46203 | L6: 10 | M6: =K6-C6 -> -1 | P6: NGN26 | Q6: 41605 | R6: 46199 | S6: 46199 | T6: --- | U6: =MIN(R6:T6) -> 46199 | V6: =MID(P6,1,LEN(P6)-3) -> NG | W6: =IFERROR(INDEX(AC:AC, MATCH(V6,AB:AB,0)),"---") -> NYMEX | Y6: подписи графиков | AB6: GC | AC6: COMEX
A7: BR-8.26 | B7: BRQ6 | C7: 46237 | D7: =MID(A7,1,SEARCH("-",A7,1)-1) -> BR | E7: BZ | F7: ="RUS:"&MID(B7,1,LEN(B7)-1)&"20"&RIGHT(A7,2)&"-"&INDEX(W:W, MATCH(J7,P:P,0))&":"&MID(J7,1,LEN(J7)-2)&"20"&RIGHT(J7,2) -> RUS:BRQ2026-NYMEX:BZU2026 | G7: =MIN(C7,K7) -> 46234 | H7: =A7 -> BR-8.26 | I7: =J7 -> BZU26 | J7: {=INDEX(P:P,MATCH(1, (V:V=E7)*(U:U>=C7-L7)*(U:U<=C7+L7), 0))} -> BZU26 | K7: =INDEX(U:U, MATCH(J7,P:P,0)) -> 46234 | L7: 10 | M7: =K7-C7 -> -3 | P7: NGQ26 | Q7: 41605 | R7: 46232 | S7: 46232 | T7: --- | U7: =MIN(R7:T7) -> 46232 | V7: =MID(P7,1,LEN(P7)-3) -> NG | W7: =IFERROR(INDEX(AC:AC, MATCH(V7,AB:AB,0)),"---") -> NYMEX | AB7: NG | AC7: NYMEX
A8: BR-9.26 | B8: BRU6 | C8: 46265 | D8: =MID(A8,1,SEARCH("-",A8,1)-1) -> BR | E8: BZ | F8: ="RUS:"&MID(B8,1,LEN(B8)-1)&"20"&RIGHT(A8,2)&"-"&INDEX(W:W, MATCH(J8,P:P,0))&":"&MID(J8,1,LEN(J8)-2)&"20"&RIGHT(J8,2) -> RUS:BRU2026-NYMEX:BZV2026 | G8: =MIN(C8,K8) -> 46262 | H8: =A8 -> BR-9.26 | I8: =J8 -> BZV26 | J8: {=INDEX(P:P,MATCH(1, (V:V=E8)*(U:U>=C8-L8)*(U:U<=C8+L8), 0))} -> BZV26 | K8: =INDEX(U:U, MATCH(J8,P:P,0)) -> 46262 | L8: 10 | M8: =K8-C8 -> -3 | P8: NGU26 | Q8: 41605 | R8: 46261 | S8: 46261 | T8: --- | U8: =MIN(R8:T8) -> 46261 | V8: =MID(P8,1,LEN(P8)-3) -> NG | W8: =IFERROR(INDEX(AC:AC, MATCH(V8,AB:AB,0)),"---") -> NYMEX | Y8: как по дате соотносить | AB8: PA | AC8: NYMEX
A9: BR-10.26 | B9: BRV6 | C9: 46296 | D9: =MID(A9,1,SEARCH("-",A9,1)-1) -> BR | E9: BZ | F9: ="RUS:"&MID(B9,1,LEN(B9)-1)&"20"&RIGHT(A9,2)&"-"&INDEX(W:W, MATCH(J9,P:P,0))&":"&MID(J9,1,LEN(J9)-2)&"20"&RIGHT(J9,2) -> RUS:BRV2026-NYMEX:BZX2026 | G9: =MIN(C9,K9) -> 46295 | H9: =A9 -> BR-10.26 | I9: =J9 -> BZX26 | J9: {=INDEX(P:P,MATCH(1, (V:V=E9)*(U:U>=C9-L9)*(U:U<=C9+L9), 0))} -> BZX26 | K9: =INDEX(U:U, MATCH(J9,P:P,0)) -> 46295 | L9: 10 | M9: =K9-C9 -> -1 | P9: NGV26 | Q9: 41605 | R9: 46293 | S9: 46293 | T9: --- | U9: =MIN(R9:T9) -> 46293 | V9: =MID(P9,1,LEN(P9)-3) -> NG | W9: =IFERROR(INDEX(AC:AC, MATCH(V9,AB:AB,0)),"---") -> NYMEX | AB9: PL | AC9: NYMEX
A10: BTC-3.26 | B10: BTH6 | C10: 46108 | D10: =MID(A10,1,SEARCH("-",A10,1)-1) -> BTC | E10: MBT | F10: ="RUS:"&MID(B10,1,LEN(B10)-1)&"20"&RIGHT(A10,2)&"-"&INDEX(W:W, MATCH(J10,P:P,0))&":"&MID(J10,1,LEN(J10)-2)&"20"&RIGHT(J10,2) -> RUS:BTH2026-CME:MBTH2026 | G10: =MIN(C10,K10) -> 46108 | H10: =A10 -> BTC-3.26 | I10: =J10 -> MBTH26 | J10: {=INDEX(P:P,MATCH(1, (V:V=E10)*(U:U>=C10-L10)*(U:U<=C10+L10), 0))} -> MBTH26 | K10: =INDEX(U:U, MATCH(J10,P:P,0)) -> 46108 | L10: 10 | M10: =K10-C10 -> 0 | P10: NGX26 | Q10: 41605 | R10: 46323 | S10: 46323 | T10: --- | U10: =MIN(R10:T10) -> 46323 | V10: =MID(P10,1,LEN(P10)-3) -> NG | W10: =IFERROR(INDEX(AC:AC, MATCH(V10,AB:AB,0)),"---") -> NYMEX | AB10: SI | AC10: COMEX
A11: BTC-4.26 | B11: BTJ6 | C11: 46136 | D11: =MID(A11,1,SEARCH("-",A11,1)-1) -> BTC | E11: MBT | F11: ="RUS:"&MID(B11,1,LEN(B11)-1)&"20"&RIGHT(A11,2)&"-"&INDEX(W:W, MATCH(J11,P:P,0))&":"&MID(J11,1,LEN(J11)-2)&"20"&RIGHT(J11,2) -> RUS:BTJ2026-CME:MBTJ2026 | G11: =MIN(C11,K11) -> 46136 | H11: =A11 -> BTC-4.26 | I11: =J11 -> MBTJ26 | J11: {=INDEX(P:P,MATCH(1, (V:V=E11)*(U:U>=C11-L11)*(U:U<=C11+L11), 0))} -> MBTJ26 | K11: =INDEX(U:U, MATCH(J11,P:P,0)) -> 46136 | L11: 10 | M11: =K11-C11 -> 0 | P11: NGZ26 | Q11: 41605 | R11: 46351 | S11: 46351 | T11: --- | U11: =MIN(R11:T11) -> 46351 | V11: =MID(P11,1,LEN(P11)-3) -> NG | W11: =IFERROR(INDEX(AC:AC, MATCH(V11,AB:AB,0)),"---") -> NYMEX | Y11: По месяцам подстановка | AB11: MGC | AC11: COMEX_MINI
A12: BTC-5.26 | B12: BTK6 | C12: 46171 | D12: =MID(A12,1,SEARCH("-",A12,1)-1) -> BTC | E12: MBT | F12: ="RUS:"&MID(B12,1,LEN(B12)-1)&"20"&RIGHT(A12,2)&"-"&INDEX(W:W, MATCH(J12,P:P,0))&":"&MID(J12,1,LEN(J12)-2)&"20"&RIGHT(J12,2) -> RUS:BTK2026-CME:MBTK2026 | G12: =MIN(C12,K12) -> 46171 | H12: =A12 -> BTC-5.26 | I12: =J12 -> MBTK26 | J12: {=INDEX(P:P,MATCH(1, (V:V=E12)*(U:U>=C12-L12)*(U:U<=C12+L12), 0))} -> MBTK26 | K12: =INDEX(U:U, MATCH(J12,P:P,0)) -> 46171 | L12: 10 | M12: =K12-C12 -> 0 | P12: NGF27 | Q12: 41969 | R12: 46385 | S12: 46385 | T12: --- | U12: =MIN(R12:T12) -> 46385 | V12: =MID(P12,1,LEN(P12)-3) -> NG | W12: =IFERROR(INDEX(AC:AC, MATCH(V12,AB:AB,0)),"---") -> NYMEX | AB12: SIL | AC12: COMEX_MINI
A13: ED-3.26 | B13: EDH6 | C13: 46100 | D13: =MID(A13,1,SEARCH("-",A13,1)-1) -> ED | E13: EC | F13: ="RUS:"&MID(B13,1,LEN(B13)-1)&"20"&RIGHT(A13,2)&"-"&INDEX(W:W, MATCH(J13,P:P,0))&":"&MID(J13,1,LEN(J13)-2)&"20"&RIGHT(J13,2) -> RUS:EDH2026-CME:ECH2026 | G13: =MIN(C13,K13) -> 46097 | H13: =A13 -> ED-3.26 | I13: =J13 -> ECH26 | J13: {=INDEX(P:P,MATCH(1, (V:V=E13)*(U:U>=C13-L13)*(U:U<=C13+L13), 0))} -> ECH26 | K13: =INDEX(U:U, MATCH(J13,P:P,0)) -> 46097 | L13: 10 | M13: =K13-C13 -> -3 | P13: NGG27 | Q13: 41969 | R13: 46414 | S13: 46414 | T13: --- | U13: =MIN(R13:T13) -> 46414 | V13: =MID(P13,1,LEN(P13)-3) -> NG | W13: =IFERROR(INDEX(AC:AC, MATCH(V13,AB:AB,0)),"---") -> NYMEX | AB13: CNH | AC13: CME
A14: ED-6.26 | B14: EDM6 | C14: 46191 | D14: =MID(A14,1,SEARCH("-",A14,1)-1) -> ED | E14: EC | F14: ="RUS:"&MID(B14,1,LEN(B14)-1)&"20"&RIGHT(A14,2)&"-"&INDEX(W:W, MATCH(J14,P:P,0))&":"&MID(J14,1,LEN(J14)-2)&"20"&RIGHT(J14,2) -> RUS:EDM2026-CME:ECM2026 | G14: =MIN(C14,K14) -> 46188 | H14: =A14 -> ED-6.26 | I14: =J14 -> ECM26 | J14: {=INDEX(P:P,MATCH(1, (V:V=E14)*(U:U>=C14-L14)*(U:U<=C14+L14), 0))} -> ECM26 | K14: =INDEX(U:U, MATCH(J14,P:P,0)) -> 46188 | L14: 10 | M14: =K14-C14 -> -3 | P14: NGH27 | Q14: 41969 | R14: 46442 | S14: 46442 | T14: --- | U14: =MIN(R14:T14) -> 46442 | V14: =MID(P14,1,LEN(P14)-3) -> NG | W14: =IFERROR(INDEX(AC:AC, MATCH(V14,AB:AB,0)),"---") -> NYMEX
A15: ED-9.26 | B15: EDU6 | C15: 46282 | D15: =MID(A15,1,SEARCH("-",A15,1)-1) -> ED | E15: EC | F15: ="RUS:"&MID(B15,1,LEN(B15)-1)&"20"&RIGHT(A15,2)&"-"&INDEX(W:W, MATCH(J15,P:P,0))&":"&MID(J15,1,LEN(J15)-2)&"20"&RIGHT(J15,2) -> RUS:EDU2026-CME:ECU2026 | G15: =MIN(C15,K15) -> 46279 | H15: =A15 -> ED-9.26 | I15: =J15 -> ECU26 | J15: {=INDEX(P:P,MATCH(1, (V:V=E15)*(U:U>=C15-L15)*(U:U<=C15+L15), 0))} -> ECU26 | K15: =INDEX(U:U, MATCH(J15,P:P,0)) -> 46279 | L15: 10 | M15: =K15-C15 -> -3 | P15: NGJ27 | Q15: 41969 | R15: 46475 | S15: 46475 | T15: --- | U15: =MIN(R15:T15) -> 46475 | V15: =MID(P15,1,LEN(P15)-3) -> NG | W15: =IFERROR(INDEX(AC:AC, MATCH(V15,AB:AB,0)),"---") -> NYMEX
A16: ED-12.26 | B16: EDZ6 | C16: 46373 | D16: =MID(A16,1,SEARCH("-",A16,1)-1) -> ED | E16: EC | F16: ="RUS:"&MID(B16,1,LEN(B16)-1)&"20"&RIGHT(A16,2)&"-"&INDEX(W:W, MATCH(J16,P:P,0))&":"&MID(J16,1,LEN(J16)-2)&"20"&RIGHT(J16,2) -> RUS:EDZ2026-CME:ECZ2026 | G16: =MIN(C16,K16) -> 46370 | H16: =A16 -> ED-12.26 | I16: =J16 -> ECZ26 | J16: {=INDEX(P:P,MATCH(1, (V:V=E16)*(U:U>=C16-L16)*(U:U<=C16+L16), 0))} -> ECZ26 | K16: =INDEX(U:U, MATCH(J16,P:P,0)) -> 46370 | L16: 10 | M16: =K16-C16 -> -3 | P16: NGK27 | Q16: 41969 | R16: 46505 | S16: 46505 | T16: --- | U16: =MIN(R16:T16) -> 46505 | V16: =MID(P16,1,LEN(P16)-3) -> NG | W16: =IFERROR(INDEX(AC:AC, MATCH(V16,AB:AB,0)),"---") -> NYMEX
A17: GOLD-3.26 | B17: GDH6 | C17: 46101 | D17: =MID(A17,1,SEARCH("-",A17,1)-1) -> GOLD | E17: GC | F17: ="RUS:"&MID(B17,1,LEN(B17)-1)&"20"&RIGHT(A17,2)&"-"&INDEX(W:W, MATCH(J17,P:P,0))&":"&MID(J17,1,LEN(J17)-2)&"20"&RIGHT(J17,2) -> RUS:GDH2026-COMEX:GCJ2026 | G17: =MIN(C17,K17) -> 46101 | H17: =A17 -> GOLD-3.26 | I17: =J17 -> GCJ26 | J17: {=INDEX(P:P,MATCH(1, (V:V=E17)*(U:U>=C17-L17)*(U:U<=C17+L17), 0))} -> GCJ26 | K17: =INDEX(U:U, MATCH(J17,P:P,0)) -> 46112 | L17: 15 | M17: =K17-C17 -> 11 | P17: NGM27 | Q17: 41969 | R17: 46533 | S17: 46533 | T17: --- | U17: =MIN(R17:T17) -> 46533 | V17: =MID(P17,1,LEN(P17)-3) -> NG | W17: =IFERROR(INDEX(AC:AC, MATCH(V17,AB:AB,0)),"---") -> NYMEX
A18: GOLD-6.26 | B18: GDM6 | C18: 46192 | D18: =MID(A18,1,SEARCH("-",A18,1)-1) -> GOLD | E18: GC | F18: ="RUS:"&MID(B18,1,LEN(B18)-1)&"20"&RIGHT(A18,2)&"-"&INDEX(W:W, MATCH(J18,P:P,0))&":"&MID(J18,1,LEN(J18)-2)&"20"&RIGHT(J18,2) -> RUS:GDM2026-COMEX:GCN2026 | G18: =MIN(C18,K18) -> 46192 | H18: =A18 -> GOLD-6.26 | I18: =J18 -> GCN26 | J18: {=INDEX(P:P,MATCH(1, (V:V=E18)*(U:U>=C18-L18)*(U:U<=C18+L18), 0))} -> GCN26 | K18: =INDEX(U:U, MATCH(J18,P:P,0)) -> 46203 | L18: 15 | M18: =K18-C18 -> 11 | P18: NGN27 | Q18: 41969 | R18: 46566 | S18: 46566 | T18: --- | U18: =MIN(R18:T18) -> 46566 | V18: =MID(P18,1,LEN(P18)-3) -> NG | W18: =IFERROR(INDEX(AC:AC, MATCH(V18,AB:AB,0)),"---") -> NYMEX
A19: GOLD-9.26 | B19: GDU6 | C19: 46283 | D19: =MID(A19,1,SEARCH("-",A19,1)-1) -> GOLD | E19: GC | F19: ="RUS:"&MID(B19,1,LEN(B19)-1)&"20"&RIGHT(A19,2)&"-"&INDEX(W:W, MATCH(J19,P:P,0))&":"&MID(J19,1,LEN(J19)-2)&"20"&RIGHT(J19,2) -> RUS:GDU2026-COMEX:GCV2026 | G19: =MIN(C19,K19) -> 46283 | H19: =A19 -> GOLD-9.26 | I19: =J19 -> GCV26 | J19: {=INDEX(P:P,MATCH(1, (V:V=E19)*(U:U>=C19-L19)*(U:U<=C19+L19), 0))} -> GCV26 | K19: =INDEX(U:U, MATCH(J19,P:P,0)) -> 46295 | L19: 15 | M19: =K19-C19 -> 12 | P19: NGQ27 | Q19: 41969 | R19: 46596 | S19: 46596 | T19: --- | U19: =MIN(R19:T19) -> 46596 | V19: =MID(P19,1,LEN(P19)-3) -> NG | W19: =IFERROR(INDEX(AC:AC, MATCH(V19,AB:AB,0)),"---") -> NYMEX
A20: GOLD-12.26 | B20: GDZ6 | C20: 46374 | D20: =MID(A20,1,SEARCH("-",A20,1)-1) -> GOLD | E20: GC | F20: ="RUS:"&MID(B20,1,LEN(B20)-1)&"20"&RIGHT(A20,2)&"-"&INDEX(W:W, MATCH(J20,P:P,0))&":"&MID(J20,1,LEN(J20)-2)&"20"&RIGHT(J20,2) -> RUS:GDZ2026-COMEX:GCF2027 | G20: =MIN(C20,K20) -> 46374 | H20: =A20 -> GOLD-12.26 | I20: =J20 -> GCF27 | J20: {=INDEX(P:P,MATCH(1, (V:V=E20)*(U:U>=C20-L20)*(U:U<=C20+L20), 0))} -> GCF27 | K20: =INDEX(U:U, MATCH(J20,P:P,0)) -> 46387 | L20: 15 | M20: =K20-C20 -> 13 | P20: NGU27 | Q20: 41969 | R20: 46626 | S20: 46626 | T20: --- | U20: =MIN(R20:T20) -> 46626 | V20: =MID(P20,1,LEN(P20)-3) -> NG | W20: =IFERROR(INDEX(AC:AC, MATCH(V20,AB:AB,0)),"---") -> NYMEX
A21: NG-3.26 | B21: NGH6 | C21: 46108 | D21: =MID(A21,1,SEARCH("-",A21,1)-1) -> NG | E21: NG | F21: ="RUS:"&MID(B21,1,LEN(B21)-1)&"20"&RIGHT(A21,2)&"-"&INDEX(W:W, MATCH(J21,P:P,0))&":"&MID(J21,1,LEN(J21)-2)&"20"&RIGHT(J21,2) -> RUS:NGH2026-NYMEX:NGJ2026 | G21: =MIN(C21,K21) -> 46108 | H21: =A21 -> NG-3.26 | I21: =J21 -> NGJ26 | J21: {=INDEX(P:P,MATCH(1, (V:V=E21)*(U:U>=C21-L21)*(U:U<=C21+L21), 0))} -> NGJ26 | K21: =INDEX(U:U, MATCH(J21,P:P,0)) -> 46108 | L21: 3 | M21: =K21-C21 -> 0 | P21: NGV27 | Q21: 41969 | R21: 46658 | S21: 46658 | T21: --- | U21: =MIN(R21:T21) -> 46658 | V21: =MID(P21,1,LEN(P21)-3) -> NG | W21: =IFERROR(INDEX(AC:AC, MATCH(V21,AB:AB,0)),"---") -> NYMEX
A22: NG-4.26 | B22: NGJ6 | C22: 46140 | D22: =MID(A22,1,SEARCH("-",A22,1)-1) -> NG | E22: NG | F22: ="RUS:"&MID(B22,1,LEN(B22)-1)&"20"&RIGHT(A22,2)&"-"&INDEX(W:W, MATCH(J22,P:P,0))&":"&MID(J22,1,LEN(J22)-2)&"20"&RIGHT(J22,2) -> RUS:NGJ2026-NYMEX:NGK2026 | G22: =MIN(C22,K22) -> 46140 | H22: =A22 -> NG-4.26 | I22: =J22 -> NGK26 | J22: {=INDEX(P:P,MATCH(1, (V:V=E22)*(U:U>=C22-L22)*(U:U<=C22+L22), 0))} -> NGK26 | K22: =INDEX(U:U, MATCH(J22,P:P,0)) -> 46140 | L22: 3 | M22: =K22-C22 -> 0 | P22: NGX27 | Q22: 41969 | R22: 46687 | S22: 46687 | T22: --- | U22: =MIN(R22:T22) -> 46687 | V22: =MID(P22,1,LEN(P22)-3) -> NG | W22: =IFERROR(INDEX(AC:AC, MATCH(V22,AB:AB,0)),"---") -> NYMEX
A23: NG-5.26 | B23: NGK6 | C23: 46169 | D23: =MID(A23,1,SEARCH("-",A23,1)-1) -> NG | E23: NG | F23: ="RUS:"&MID(B23,1,LEN(B23)-1)&"20"&RIGHT(A23,2)&"-"&INDEX(W:W, MATCH(J23,P:P,0))&":"&MID(J23,1,LEN(J23)-2)&"20"&RIGHT(J23,2) -> RUS:NGK2026-NYMEX:NGM2026 | G23: =MIN(C23,K23) -> 46169 | H23: =A23 -> NG-5.26 | I23: =J23 -> NGM26 | J23: {=INDEX(P:P,MATCH(1, (V:V=E23)*(U:U>=C23-L23)*(U:U<=C23+L23), 0))} -> NGM26 | K23: =INDEX(U:U, MATCH(J23,P:P,0)) -> 46169 | L23: 3 | M23: =K23-C23 -> 0 | P23: NGZ27 | Q23: 41969 | R23: 46717 | S23: 46717 | T23: --- | U23: =MIN(R23:T23) -> 46717 | V23: =MID(P23,1,LEN(P23)-3) -> NG | W23: =IFERROR(INDEX(AC:AC, MATCH(V23,AB:AB,0)),"---") -> NYMEX
A24: NG-6.26 | B24: NGM6 | C24: 46199 | D24: =MID(A24,1,SEARCH("-",A24,1)-1) -> NG | E24: NG | F24: ="RUS:"&MID(B24,1,LEN(B24)-1)&"20"&RIGHT(A24,2)&"-"&INDEX(W:W, MATCH(J24,P:P,0))&":"&MID(J24,1,LEN(J24)-2)&"20"&RIGHT(J24,2) -> RUS:NGM2026-NYMEX:NGN2026 | G24: =MIN(C24,K24) -> 46199 | H24: =A24 -> NG-6.26 | I24: =J24 -> NGN26 | J24: {=INDEX(P:P,MATCH(1, (V:V=E24)*(U:U>=C24-L24)*(U:U<=C24+L24), 0))} -> NGN26 | K24: =INDEX(U:U, MATCH(J24,P:P,0)) -> 46199 | L24: 3 | M24: =K24-C24 -> 0 | P24: NGF28 | Q24: 42335 | R24: 46750 | S24: 46750 | T24: --- | U24: =MIN(R24:T24) -> 46750 | V24: =MID(P24,1,LEN(P24)-3) -> NG | W24: =IFERROR(INDEX(AC:AC, MATCH(V24,AB:AB,0)),"---") -> NYMEX
A25: NG-7.26 | B25: NGN6 | C25: 46232 | D25: =MID(A25,1,SEARCH("-",A25,1)-1) -> NG | E25: NG | F25: ="RUS:"&MID(B25,1,LEN(B25)-1)&"20"&RIGHT(A25,2)&"-"&INDEX(W:W, MATCH(J25,P:P,0))&":"&MID(J25,1,LEN(J25)-2)&"20"&RIGHT(J25,2) -> RUS:NGN2026-NYMEX:NGQ2026 | G25: =MIN(C25,K25) -> 46232 | H25: =A25 -> NG-7.26 | I25: =J25 -> NGQ26 | J25: {=INDEX(P:P,MATCH(1, (V:V=E25)*(U:U>=C25-L25)*(U:U<=C25+L25), 0))} -> NGQ26 | K25: =INDEX(U:U, MATCH(J25,P:P,0)) -> 46232 | L25: 3 | M25: =K25-C25 -> 0 | P25: NGG28 | Q25: 42335 | R25: 46779 | S25: 46779 | T25: --- | U25: =MIN(R25:T25) -> 46779 | V25: =MID(P25,1,LEN(P25)-3) -> NG | W25: =IFERROR(INDEX(AC:AC, MATCH(V25,AB:AB,0)),"---") -> NYMEX
... A46: SILV-9.26 | B46: SVU6 | C46: 46283 | D46: =MID(A46,1,SEARCH("-",A46,1)-1) -> SILV | E46: SIL | F46: ="RUS:"&MID(B46,1,LEN(B46)-1)&"20"&RIGHT(A46,2)&"-"&INDEX(W:W, MATCH(J46,P:P,0))&":"&MID(J46,1,LEN(J46)-2)&"20"&RIGHT(J46,2) -> #N/A | G46: =MIN(C46,K46) -> #N/A | H46: =A46 -> SILV-9.26 | I46: =J46 -> #N/A | J46: {=INDEX(P:P,MATCH(1, (V:V=E46)*(U:U>=C46-L46)*(U:U<=C46+L46), 0))} -> #N/A | K46: =INDEX(U:U, MATCH(J46,P:P,0)) -> #N/A | L46: 15 | M46: =K46-C46 -> #N/A | P46: NGX29 | Q46: 42703 | R46: 47420 | S46: 47420 | T46: --- | U46: =MIN(R46:T46) -> 47420 | V46: =MID(P46,1,LEN(P46)-3) -> NG | W46: =IFERROR(INDEX(AC:AC, MATCH(V46,AB:AB,0)),"---") -> NYMEX
A47: UCNY-3.26 | B47: UCH6 | C47: 46100 | D47: =MID(A47,1,SEARCH("-",A47,1)-1) -> UCNY | E47: CNH | F47: ="RUS:"&MID(B47,1,LEN(B47)-1)&"20"&RIGHT(A47,2)&"-"&INDEX(W:W, MATCH(J47,P:P,0))&":"&MID(J47,1,LEN(J47)-2)&"20"&RIGHT(J47,2) -> #N/A | G47: =MIN(C47,K47) -> #N/A | H47: =A47 -> UCNY-3.26 | I47: =J47 -> #N/A | J47: {=INDEX(P:P,MATCH(1, (V:V=E47)*(U:U>=C47-L47)*(U:U<=C47+L47), 0))} -> #N/A | K47: =INDEX(U:U, MATCH(J47,P:P,0)) -> #N/A | M47: =K47-C47 -> #N/A | P47: NGZ29 | Q47: 42703 | R47: 47450 | S47: 47450 | T47: --- | U47: =MIN(R47:T47) -> 47450 | V47: =MID(P47,1,LEN(P47)-3) -> NG | W47: =IFERROR(INDEX(AC:AC, MATCH(V47,AB:AB,0)),"---") -> NYMEX
A48: UCNY-6.26 | B48: UCM6 | C48: 46191 | D48: =MID(A48,1,SEARCH("-",A48,1)-1) -> UCNY | E48: CNH | F48: ="RUS:"&MID(B48,1,LEN(B48)-1)&"20"&RIGHT(A48,2)&"-"&INDEX(W:W, MATCH(J48,P:P,0))&":"&MID(J48,1,LEN(J48)-2)&"20"&RIGHT(J48,2) -> #N/A | G48: =MIN(C48,K48) -> #N/A | H48: =A48 -> UCNY-6.26 | I48: =J48 -> #N/A | J48: {=INDEX(P:P,MATCH(1, (V:V=E48)*(U:U>=C48-L48)*(U:U<=C48+L48), 0))} -> #N/A | K48: =INDEX(U:U, MATCH(J48,P:P,0)) -> #N/A | M48: =K48-C48 -> #N/A | P48: NGF30 | Q48: 43068 | R48: 47479 | S48: 47479 | T48: --- | U48: =MIN(R48:T48) -> 47479 | V48: =MID(P48,1,LEN(P48)-3) -> NG | W48: =IFERROR(INDEX(AC:AC, MATCH(V48,AB:AB,0)),"---") -> NYMEX
A49: UCNY-9.26 | B49: UCU6 | C49: 46282 | D49: =MID(A49,1,SEARCH("-",A49,1)-1) -> UCNY | E49: CNH | F49: ="RUS:"&MID(B49,1,LEN(B49)-1)&"20"&RIGHT(A49,2)&"-"&INDEX(W:W, MATCH(J49,P:P,0))&":"&MID(J49,1,LEN(J49)-2)&"20"&RIGHT(J49,2) -> #N/A | G49: =MIN(C49,K49) -> #N/A | H49: =A49 -> UCNY-9.26 | I49: =J49 -> #N/A | J49: {=INDEX(P:P,MATCH(1, (V:V=E49)*(U:U>=C49-L49)*(U:U<=C49+L49), 0))} -> #N/A | K49: =INDEX(U:U, MATCH(J49,P:P,0)) -> #N/A | M49: =K49-C49 -> #N/A | P49: NGG30 | Q49: 43068 | R49: 47512 | S49: 47512 | T49: --- | U49: =MIN(R49:T49) -> 47512 | V49: =MID(P49,1,LEN(P49)-3) -> NG | W49: =IFERROR(INDEX(AC:AC, MATCH(V49,AB:AB,0)),"---") -> NYMEX
A50: UCNY-12.26 | B50: UCZ6 | C50: 46373 | D50: =MID(A50,1,SEARCH("-",A50,1)-1) -> UCNY | E50: CNH | F50: ="RUS:"&MID(B50,1,LEN(B50)-1)&"20"&RIGHT(A50,2)&"-"&INDEX(W:W, MATCH(J50,P:P,0))&":"&MID(J50,1,LEN(J50)-2)&"20"&RIGHT(J50,2) -> #N/A | G50: =MIN(C50,K50) -> #N/A | H50: =A50 -> UCNY-12.26 | I50: =J50 -> #N/A | J50: {=INDEX(P:P,MATCH(1, (V:V=E50)*(U:U>=C50-L50)*(U:U<=C50+L50), 0))} -> #N/A | K50: =INDEX(U:U, MATCH(J50,P:P,0)) -> #N/A | M50: =K50-C50 -> #N/A | P50: NGH30 | Q50: 43068 | R50: 47540 | S50: 47540 | T50: --- | U50: =MIN(R50:T50) -> 47540 | V50: =MID(P50,1,LEN(P50)-3) -> NG | W50: =IFERROR(INDEX(AC:AC, MATCH(V50,AB:AB,0)),"---") -> NYMEX
P51: NGJ30 | Q51: 43068 | R51: 47569 | S51: 47569 | T51: --- | U51: =MIN(R51:T51) -> 47569 | V51: =MID(P51,1,LEN(P51)-3) -> NG | W51: =IFERROR(INDEX(AC:AC, MATCH(V51,AB:AB,0)),"---") -> NYMEX
P52: NGK30 | Q52: 43068 | R52: 47599 | S52: 47599 | T52: --- | U52: =MIN(R52:T52) -> 47599 | V52: =MID(P52,1,LEN(P52)-3) -> NG | W52: =IFERROR(INDEX(AC:AC, MATCH(V52,AB:AB,0)),"---") -> NYMEX
P53: NGM30 | Q53: 43068 | R53: 47632 | S53: 47632 | T53: --- | U53: =MIN(R53:T53) -> 47632 | V53: =MID(P53,1,LEN(P53)-3) -> NG | W53: =IFERROR(INDEX(AC:AC, MATCH(V53,AB:AB,0)),"---") -> NYMEX
P54: NGN30 | Q54: 43068 | R54: 47660 | S54: 47660 | T54: --- | U54: =MIN(R54:T54) -> 47660 | V54: =MID(P54,1,LEN(P54)-3) -> NG | W54: =IFERROR(INDEX(AC:AC, MATCH(V54,AB:AB,0)),"---") -> NYMEX
P55: NGQ30 | Q55: 43068 | R55: 47693 | S55: 47693 | T55: --- | U55: =MIN(R55:T55) -> 47693 | V55: =MID(P55,1,LEN(P55)-3) -> NG | W55: =IFERROR(INDEX(AC:AC, MATCH(V55,AB:AB,0)),"---") -> NYMEX
P56: NGU30 | Q56: 43068 | R56: 47723 | S56: 47723 | T56: --- | U56: =MIN(R56:T56) -> 47723 | V56: =MID(P56,1,LEN(P56)-3) -> NG | W56: =IFERROR(INDEX(AC:AC, MATCH(V56,AB:AB,0)),"---") -> NYMEX
P57: NGV30 | Q57: 43068 | R57: 47752 | S57: 47752 | T57: --- | U57: =MIN(R57:T57) -> 47752 | V57: =MID(P57,1,LEN(P57)-3) -> NG | W57: =IFERROR(INDEX(AC:AC, MATCH(V57,AB:AB,0)),"---") -> NYMEX
P58: NGX30 | Q58: 43068 | R58: 47785 | S58: 47785 | T58: --- | U58: =MIN(R58:T58) -> 47785 | V58: =MID(P58,1,LEN(P58)-3) -> NG | W58: =IFERROR(INDEX(AC:AC, MATCH(V58,AB:AB,0)),"---") -> NYMEX
P59: NGZ30 | Q59: 43068 | R59: 47813 | S59: 47813 | T59: --- | U59: =MIN(R59:T59) -> 47813 | V59: =MID(P59,1,LEN(P59)-3) -> NG | W59: =IFERROR(INDEX(AC:AC, MATCH(V59,AB:AB,0)),"---") -> NYMEX
P60: NGF31 | Q60: 43433 | R60: 47844 | S60: 47844 | T60: --- | U60: =MIN(R60:T60) -> 47844 | V60: =MID(P60,1,LEN(P60)-3) -> NG | W60: =IFERROR(INDEX(AC:AC, MATCH(V60,AB:AB,0)),"---") -> NYMEX
P61: NGG31 | Q61: 43433 | R61: 47877 | S61: 47877 | T61: --- | U61: =MIN(R61:T61) -> 47877 | V61: =MID(P61,1,LEN(P61)-3) -> NG | W61: =IFERROR(INDEX(AC:AC, MATCH(V61,AB:AB,0)),"---") -> NYMEX
...

Sheet CME Data
A1: Input 2nd Leg | F1: Additional 2nd Leg | I1: Leg 1 | N1: Exchange
A2: Product Code | B2: First Trade | C2: Last Trade | D2: Settlement | E2: FND | F2: Final Date | G2: Underl CME | H2: Exch | I2: Moex 1 | J2: Exp 1 | K2: Spread Date | N2: Underl2 | O2: Exch
A3: NGJ26 | B3: 41605 | C3: 46108 | D3: 46108 | E3: --- | F3: =MIN(C3:E3) -> 46108 | G3: =MID(A3,1,LEN(A3)-3) -> NG | H3: =IFERROR(INDEX(O:O, MATCH(G3,N:N,0)),"---") -> NYMEX | I3: {=IFERROR(INDEX(Spreads!A:A,MATCH(1, (Spreads!E:E=G3)*(Spreads!C:C>=F3), 0)),"---")} -> NG-3.26 | J3: =IFERROR(INDEX(Spreads!C:C, MATCH('CME Data'!I3,Spreads!A:A,0)),"---") -> 46108 | K3: =MIN(J3,F3) -> 46108 | N3: BZ | O3: NYMEX
A4: NGK26 | B4: 41605 | C4: 46140 | D4: 46140 | E4: --- | F4: =MIN(C4:E4) -> 46140 | G4: =MID(A4,1,LEN(A4)-3) -> NG | H4: =IFERROR(INDEX(O:O, MATCH(G4,N:N,0)),"---") -> NYMEX | I4: {=IFERROR(INDEX(Spreads!A:A,MATCH(1, (Spreads!E:E=G4)*(Spreads!C:C>=F4), 0)),"---")} -> NG-4.26 | J4: =IFERROR(INDEX(Spreads!C:C, MATCH('CME Data'!I4,Spreads!A:A,0)),"---") -> 46140 | K4: =MIN(J4,F4) -> 46140 | N4: MBT | O4: CME
A5: NGM26 | B5: 41605 | C5: 46169 | D5: 46169 | E5: --- | F5: =MIN(C5:E5) -> 46169 | G5: =MID(A5,1,LEN(A5)-3) -> NG | H5: =IFERROR(INDEX(O:O, MATCH(G5,N:N,0)),"---") -> NYMEX | I5: {=IFERROR(INDEX(Spreads!A:A,MATCH(1, (Spreads!E:E=G5)*(Spreads!C:C>=F5), 0)),"---")} -> NG-5.26 | J5: =IFERROR(INDEX(Spreads!C:C, MATCH('CME Data'!I5,Spreads!A:A,0)),"---") -> 46169 | K5: =MIN(J5,F5) -> 46169 | N5: EC | O5: CME
A6: NGN26 | B6: 41605 | C6: 46199 | D6: 46199 | E6: --- | F6: =MIN(C6:E6) -> 46199 | G6: =MID(A6,1,LEN(A6)-3) -> NG | H6: =IFERROR(INDEX(O:O, MATCH(G6,N:N,0)),"---") -> NYMEX | I6: {=IFERROR(INDEX(Spreads!A:A,MATCH(1, (Spreads!E:E=G6)*(Spreads!C:C>=F6), 0)),"---")} -> NG-6.26 | J6: =IFERROR(INDEX(Spreads!C:C, MATCH('CME Data'!I6,Spreads!A:A,0)),"---") -> 46199 | K6: =MIN(J6,F6) -> 46199 | N6: GC | O6: COMEX
A7: NGQ26 | B7: 41605 | C7: 46232 | D7: 46232 | E7: --- | F7: =MIN(C7:E7) -> 46232 | G7: =MID(A7,1,LEN(A7)-3) -> NG | H7: =IFERROR(INDEX(O:O, MATCH(G7,N:N,0)),"---") -> NYMEX | I7: {=IFERROR(INDEX(Spreads!A:A,MATCH(1, (Spreads!E:E=G7)*(Spreads!C:C>=F7), 0)),"---")} -> NG-7.26 | J7: =IFERROR(INDEX(Spreads!C:C, MATCH('CME Data'!I7,Spreads!A:A,0)),"---") -> 46232 | K7: =MIN(J7,F7) -> 46232 | N7: NG | O7: NYMEX
A8: NGU26 | B8: 41605 | C8: 46261 | D8: 46261 | E8: --- | F8: =MIN(C8:E8) -> 46261 | G8: =MID(A8,1,LEN(A8)-3) -> NG | H8: =IFERROR(INDEX(O:O, MATCH(G8,N:N,0)),"---") -> NYMEX | I8: {=IFERROR(INDEX(Spreads!A:A,MATCH(1, (Spreads!E:E=G8)*(Spreads!C:C>=F8), 0)),"---")} -> NG-8.26 | J8: =IFERROR(INDEX(Spreads!C:C, MATCH('CME Data'!I8,Spreads!A:A,0)),"---") -> 46261 | K8: =MIN(J8,F8) -> 46261 | N8: PA | O8: NYMEX
A9: NGV26 | B9: 41605 | C9: 46293 | D9: 46293 | E9: --- | F9: =MIN(C9:E9) -> 46293 | G9: =MID(A9,1,LEN(A9)-3) -> NG | H9: =IFERROR(INDEX(O:O, MATCH(G9,N:N,0)),"---") -> NYMEX | I9: {=IFERROR(INDEX(Spreads!A:A,MATCH(1, (Spreads!E:E=G9)*(Spreads!C:C>=F9), 0)),"---")} -> NG-9.26 | J9: =IFERROR(INDEX(Spreads!C:C, MATCH('CME Data'!I9,Spreads!A:A,0)),"---") -> 46293 | K9: =MIN(J9,F9) -> 46293 | N9: PL | O9: NYMEX
A10: NGX26 | B10: 41605 | C10: 46323 | D10: 46323 | E10: --- | F10: =MIN(C10:E10) -> 46323 | G10: =MID(A10,1,LEN(A10)-3) -> NG | H10: =IFERROR(INDEX(O:O, MATCH(G10,N:N,0)),"---") -> NYMEX | I10: {=IFERROR(INDEX(Spreads!A:A,MATCH(1, (Spreads!E:E=G10)*(Spreads!C:C>=F10), 0)),"---")} -> --- | J10: =IFERROR(INDEX(Spreads!C:C, MATCH('CME Data'!I10,Spreads!A:A,0)),"---") -> --- | K10: =MIN(J10,F10) -> 46323 | N10: SI | O10: COMEX
A11: NGZ26 | B11: 41605 | C11: 46351 | D11: 46351 | E11: --- | F11: =MIN(C11:E11) -> 46351 | G11: =MID(A11,1,LEN(A11)-3) -> NG | H11: =IFERROR(INDEX(O:O, MATCH(G11,N:N,0)),"---") -> NYMEX | I11: {=IFERROR(INDEX(Spreads!A:A,MATCH(1, (Spreads!E:E=G11)*(Spreads!C:C>=F11), 0)),"---")} -> --- | J11: =IFERROR(INDEX(Spreads!C:C, MATCH('CME Data'!I11,Spreads!A:A,0)),"---") -> --- | K11: =MIN(J11,F11) -> 46351 | N11: MGC | O11: COMEX_MINI
A12: NGF27 | B12: 41969 | C12: 46385 | D12: 46385 | E12: --- | F12: =MIN(C12:E12) -> 46385 | G12: =MID(A12,1,LEN(A12)-3) -> NG | H12: =IFERROR(INDEX(O:O, MATCH(G12,N:N,0)),"---") -> NYMEX | I12: {=IFERROR(INDEX(Spreads!A:A,MATCH(1, (Spreads!E:E=G12)*(Spreads!C:C>=F12), 0)),"---")} -> --- | J12: =IFERROR(INDEX(Spreads!C:C, MATCH('CME Data'!I12,Spreads!A:A,0)),"---") -> --- | K12: =MIN(J12,F12) -> 46385 | N12: SIL | O12: COMEX_MINI
